[2016-12-12 22:33:57] DEBUG [django.db.backends:89] (0.084) 
            SELECT name, type FROM sqlite_master
            WHERE type in ('table', 'view') AND NOT name='sqlite_sequence'
            ORDER BY name; args=None
[2016-12-12 22:33:57] DEBUG [django.db.backends:89] (0.000) SELECT "django_migrations"."app", "django_migrations"."name" FROM "django_migrations"; args=()
[2016-12-12 22:34:17] DEBUG [django.db.backends:89] (0.001) SELECT "oauth2_provider_application"."id", "oauth2_provider_application"."client_id", "oauth2_provider_application"."user_id", "oauth2_provider_application"."redirect_uris", "oauth2_provider_application"."client_type", "oauth2_provider_application"."authorization_grant_type", "oauth2_provider_application"."client_secret", "oauth2_provider_application"."name", "oauth2_provider_application"."skip_authorization" FROM "oauth2_provider_application" WHERE "oauth2_provider_application"."client_id" = 'NKIYrU2hAJfg7jBoffVOHYCbgfv1V9iGjKIa7CdQ'; args=('NKIYrU2hAJfg7jBoffVOHYCbgfv1V9iGjKIa7CdQ',)
[2016-12-12 22:34:17] DEBUG [django.db.backends:89] (0.000) SELECT "auths_user"."password", "auths_user"."last_login", "auths_user"."is_superuser", "auths_user"."username", "auths_user"."first_name", "auths_user"."last_name", "auths_user"."email", "auths_user"."is_staff", "auths_user"."is_active", "auths_user"."date_joined", "auths_user"."id", "auths_user"."last_hierarchy_id", "auths_user"."last_module_id", "auths_user"."person_id", "auths_user"."updated_at", "auths_user"."registered_by" FROM "auths_user" WHERE "auths_user"."username" = 'admin'; args=('admin',)
[2016-12-12 22:34:27] DEBUG [django.db.backends:89] (0.001) SELECT "django_session"."session_key", "django_session"."session_data", "django_session"."expire_date" FROM "django_session" WHERE ("django_session"."session_key" = '4brnqfz7re4re4ga7gc5v00omfi9ch05' AND "django_session"."expire_date" > '2016-12-12 22:34:27.866447'); args=('4brnqfz7re4re4ga7gc5v00omfi9ch05', '2016-12-12 22:34:27.866447')
[2016-12-12 22:34:28] DEBUG [django.template:927] Exception while resolving variable 'is_popup' in template 'admin/login.html'.
Traceback (most recent call last):
  File "/home/roger/.virtualenvs/learning/lib/python3.5/site-packages/django/template/base.py", line 883, in _resolve_lookup
    current = current[bit]
  File "/home/roger/.virtualenvs/learning/lib/python3.5/site-packages/django/template/context.py", line 77, in __getitem__
    raise KeyError(key)
KeyError: 'is_popup'

During handling of the above exception, another exception occurred:

Traceback (most recent call last):
  File "/home/roger/.virtualenvs/learning/lib/python3.5/site-packages/django/template/base.py", line 889, in _resolve_lookup
    if isinstance(current, BaseContext) and getattr(type(current), bit):
AttributeError: type object 'RequestContext' has no attribute 'is_popup'

During handling of the above exception, another exception occurred:

Traceback (most recent call last):
  File "/home/roger/.virtualenvs/learning/lib/python3.5/site-packages/django/template/base.py", line 898, in _resolve_lookup
    current = current[int(bit)]
ValueError: invalid literal for int() with base 10: 'is_popup'

During handling of the above exception, another exception occurred:

Traceback (most recent call last):
  File "/home/roger/.virtualenvs/learning/lib/python3.5/site-packages/django/template/base.py", line 905, in _resolve_lookup
    (bit, current))  # missing attribute
django.template.base.VariableDoesNotExist: Failed lookup for key [is_popup] in "[{'False': False, 'True': True, 'None': None}, {'csrf_token': <SimpleLazyObject: <function csrf.<locals>._get_val at 0x7f7aaea2cf28>>, 'messages': <django.contrib.messages.storage.fallback.FallbackStorage object at 0x7f7aafa9b710>, 'user': <SimpleLazyObject: <django.contrib.auth.models.AnonymousUser object at 0x7f7aafa9b898>>, 'DEFAULT_MESSAGE_LEVELS': {'DEBUG': 10, 'SUCCESS': 25, 'WARNING': 30, 'ERROR': 40, 'INFO': 20}, 'request': <WSGIRequest: GET '/admin/login/?next=/admin/'>, 'perms': <django.contrib.auth.context_processors.PermWrapper object at 0x7f7aad7b9f60>}, {}, {'site_title': <django.utils.functional.lazy.<locals>.__proxy__ object at 0x7f7ab5bc25c0>, 'title': 'Log in', 'LANGUAGE_CODE': 'en-us', 'next': '/admin/', 'has_permission': False, 'site_url': '/', 'site_header': <django.utils.functional.lazy.<locals>.__proxy__ object at 0x7f7ab5b5f470>, 'available_apps': [], 'app_path': '/admin/login/?next=/admin/', 'LANGUAGE_BIDI': False, 'site': <django.contrib.sites.requests.RequestSite object at 0x7f7aafcccba8>, 'form': <AdminAuthenticationForm bound=False, valid=Unknown, fields=(username;password)>, 'site_name': 'localhost:9001'}]"
[2016-12-12 22:34:28] DEBUG [django.template:927] Exception while resolving variable 'is_popup' in template 'admin/login.html'.
Traceback (most recent call last):
  File "/home/roger/.virtualenvs/learning/lib/python3.5/site-packages/django/template/base.py", line 883, in _resolve_lookup
    current = current[bit]
  File "/home/roger/.virtualenvs/learning/lib/python3.5/site-packages/django/template/context.py", line 77, in __getitem__
    raise KeyError(key)
KeyError: 'is_popup'

During handling of the above exception, another exception occurred:

Traceback (most recent call last):
  File "/home/roger/.virtualenvs/learning/lib/python3.5/site-packages/django/template/base.py", line 889, in _resolve_lookup
    if isinstance(current, BaseContext) and getattr(type(current), bit):
AttributeError: type object 'RequestContext' has no attribute 'is_popup'

During handling of the above exception, another exception occurred:

Traceback (most recent call last):
  File "/home/roger/.virtualenvs/learning/lib/python3.5/site-packages/django/template/base.py", line 898, in _resolve_lookup
    current = current[int(bit)]
ValueError: invalid literal for int() with base 10: 'is_popup'

During handling of the above exception, another exception occurred:

Traceback (most recent call last):
  File "/home/roger/.virtualenvs/learning/lib/python3.5/site-packages/django/template/base.py", line 905, in _resolve_lookup
    (bit, current))  # missing attribute
django.template.base.VariableDoesNotExist: Failed lookup for key [is_popup] in "[{'False': False, 'True': True, 'None': None}, {'csrf_token': <SimpleLazyObject: <function csrf.<locals>._get_val at 0x7f7aaea2cf28>>, 'messages': <django.contrib.messages.storage.fallback.FallbackStorage object at 0x7f7aafa9b710>, 'user': <SimpleLazyObject: <django.contrib.auth.models.AnonymousUser object at 0x7f7aafa9b898>>, 'DEFAULT_MESSAGE_LEVELS': {'DEBUG': 10, 'SUCCESS': 25, 'WARNING': 30, 'ERROR': 40, 'INFO': 20}, 'request': <WSGIRequest: GET '/admin/login/?next=/admin/'>, 'perms': <django.contrib.auth.context_processors.PermWrapper object at 0x7f7aad7b9f60>}, {}, {'site_title': <django.utils.functional.lazy.<locals>.__proxy__ object at 0x7f7ab5bc25c0>, 'title': 'Log in', 'LANGUAGE_CODE': 'en-us', 'next': '/admin/', 'has_permission': False, 'site_url': '/', 'site_header': <django.utils.functional.lazy.<locals>.__proxy__ object at 0x7f7ab5b5f470>, 'available_apps': [], 'app_path': '/admin/login/?next=/admin/', 'LANGUAGE_BIDI': False, 'site': <django.contrib.sites.requests.RequestSite object at 0x7f7aafcccba8>, 'form': <AdminAuthenticationForm bound=False, valid=Unknown, fields=(username;password)>, 'site_name': 'localhost:9001'}]"
[2016-12-12 22:34:29] WARNING [django.request:182] Not Found: /favicon.ico
[2016-12-12 22:34:29] DEBUG [django.template:927] Exception while resolving variable 'name' in template 'unknown'.
Traceback (most recent call last):
  File "/home/roger/.virtualenvs/learning/lib/python3.5/site-packages/django/core/handlers/base.py", line 134, in get_response
    resolver_match = resolver.resolve(request.path_info)
  File "/home/roger/.virtualenvs/learning/lib/python3.5/site-packages/django/core/urlresolvers.py", line 404, in resolve
    raise Resolver404({'tried': tried, 'path': new_path})
django.core.urlresolvers.Resolver404: {'path': 'favicon.ico', 'tried': [[<RegexURLResolver <RegexURLPattern list> (admin:admin) ^admin/>], [<RegexURLResolver <module 'django.contrib.admindocs.urls' from '/home/roger/.virtualenvs/learning/lib/python3.5/site-packages/django/contrib/admindocs/urls.py'> (None:None) ^admin/doc/>], [<RegexURLResolver <module 'rest_framework.urls' from '/home/roger/.virtualenvs/learning/lib/python3.5/site-packages/rest_framework/urls.py'> (rest_framework:rest_framework) ^api-auth/>], [<RegexURLResolver <module 'oauth2_provider.urls' from '/home/roger/.virtualenvs/learning/lib/python3.5/site-packages/oauth2_provider/urls.py'> (None:oauth2_provider) ^o/>], [<RegexURLResolver <module 'ioteca_service_apps.auths_api.urls' from '/home/roger/proyectos/learning/learning/ioteca_service/ioteca_service_apps/auths_api/urls.py'> (None:None) ^api/auths/>], [<RegexURLResolver <module 'ioteca_service_apps.dper.urls' from '/home/roger/proyectos/learning/learning/ioteca_service/ioteca_service_apps/dper/urls.py'> (None:None) ^api/dper/>]]}

During handling of the above exception, another exception occurred:

Traceback (most recent call last):
  File "/home/roger/.virtualenvs/learning/lib/python3.5/site-packages/django/template/base.py", line 883, in _resolve_lookup
    current = current[bit]
TypeError: 'RegexURLResolver' object is not subscriptable

During handling of the above exception, another exception occurred:

Traceback (most recent call last):
  File "/home/roger/.virtualenvs/learning/lib/python3.5/site-packages/django/template/base.py", line 891, in _resolve_lookup
    current = getattr(current, bit)
AttributeError: 'RegexURLResolver' object has no attribute 'name'

During handling of the above exception, another exception occurred:

Traceback (most recent call last):
  File "/home/roger/.virtualenvs/learning/lib/python3.5/site-packages/django/template/base.py", line 898, in _resolve_lookup
    current = current[int(bit)]
ValueError: invalid literal for int() with base 10: 'name'

During handling of the above exception, another exception occurred:

Traceback (most recent call last):
  File "/home/roger/.virtualenvs/learning/lib/python3.5/site-packages/django/template/base.py", line 905, in _resolve_lookup
    (bit, current))  # missing attribute
django.template.base.VariableDoesNotExist: Failed lookup for key [name] in '<RegexURLResolver <RegexURLPattern list> (admin:admin) ^admin/>'
[2016-12-12 22:34:29] DEBUG [django.template:927] Exception while resolving variable 'name' in template 'unknown'.
Traceback (most recent call last):
  File "/home/roger/.virtualenvs/learning/lib/python3.5/site-packages/django/core/handlers/base.py", line 134, in get_response
    resolver_match = resolver.resolve(request.path_info)
  File "/home/roger/.virtualenvs/learning/lib/python3.5/site-packages/django/core/urlresolvers.py", line 404, in resolve
    raise Resolver404({'tried': tried, 'path': new_path})
django.core.urlresolvers.Resolver404: {'path': 'favicon.ico', 'tried': [[<RegexURLResolver <RegexURLPattern list> (admin:admin) ^admin/>], [<RegexURLResolver <module 'django.contrib.admindocs.urls' from '/home/roger/.virtualenvs/learning/lib/python3.5/site-packages/django/contrib/admindocs/urls.py'> (None:None) ^admin/doc/>], [<RegexURLResolver <module 'rest_framework.urls' from '/home/roger/.virtualenvs/learning/lib/python3.5/site-packages/rest_framework/urls.py'> (rest_framework:rest_framework) ^api-auth/>], [<RegexURLResolver <module 'oauth2_provider.urls' from '/home/roger/.virtualenvs/learning/lib/python3.5/site-packages/oauth2_provider/urls.py'> (None:oauth2_provider) ^o/>], [<RegexURLResolver <module 'ioteca_service_apps.auths_api.urls' from '/home/roger/proyectos/learning/learning/ioteca_service/ioteca_service_apps/auths_api/urls.py'> (None:None) ^api/auths/>], [<RegexURLResolver <module 'ioteca_service_apps.dper.urls' from '/home/roger/proyectos/learning/learning/ioteca_service/ioteca_service_apps/dper/urls.py'> (None:None) ^api/dper/>]]}

During handling of the above exception, another exception occurred:

Traceback (most recent call last):
  File "/home/roger/.virtualenvs/learning/lib/python3.5/site-packages/django/template/base.py", line 883, in _resolve_lookup
    current = current[bit]
TypeError: 'RegexURLResolver' object is not subscriptable

During handling of the above exception, another exception occurred:

Traceback (most recent call last):
  File "/home/roger/.virtualenvs/learning/lib/python3.5/site-packages/django/template/base.py", line 891, in _resolve_lookup
    current = getattr(current, bit)
AttributeError: 'RegexURLResolver' object has no attribute 'name'

During handling of the above exception, another exception occurred:

Traceback (most recent call last):
  File "/home/roger/.virtualenvs/learning/lib/python3.5/site-packages/django/template/base.py", line 898, in _resolve_lookup
    current = current[int(bit)]
ValueError: invalid literal for int() with base 10: 'name'

During handling of the above exception, another exception occurred:

Traceback (most recent call last):
  File "/home/roger/.virtualenvs/learning/lib/python3.5/site-packages/django/template/base.py", line 905, in _resolve_lookup
    (bit, current))  # missing attribute
django.template.base.VariableDoesNotExist: Failed lookup for key [name] in "<RegexURLResolver <module 'django.contrib.admindocs.urls' from '/home/roger/.virtualenvs/learning/lib/python3.5/site-packages/django/contrib/admindocs/urls.py'> (None:None) ^admin/doc/>"
[2016-12-12 22:34:29] DEBUG [django.template:927] Exception while resolving variable 'name' in template 'unknown'.
Traceback (most recent call last):
  File "/home/roger/.virtualenvs/learning/lib/python3.5/site-packages/django/core/handlers/base.py", line 134, in get_response
    resolver_match = resolver.resolve(request.path_info)
  File "/home/roger/.virtualenvs/learning/lib/python3.5/site-packages/django/core/urlresolvers.py", line 404, in resolve
    raise Resolver404({'tried': tried, 'path': new_path})
django.core.urlresolvers.Resolver404: {'path': 'favicon.ico', 'tried': [[<RegexURLResolver <RegexURLPattern list> (admin:admin) ^admin/>], [<RegexURLResolver <module 'django.contrib.admindocs.urls' from '/home/roger/.virtualenvs/learning/lib/python3.5/site-packages/django/contrib/admindocs/urls.py'> (None:None) ^admin/doc/>], [<RegexURLResolver <module 'rest_framework.urls' from '/home/roger/.virtualenvs/learning/lib/python3.5/site-packages/rest_framework/urls.py'> (rest_framework:rest_framework) ^api-auth/>], [<RegexURLResolver <module 'oauth2_provider.urls' from '/home/roger/.virtualenvs/learning/lib/python3.5/site-packages/oauth2_provider/urls.py'> (None:oauth2_provider) ^o/>], [<RegexURLResolver <module 'ioteca_service_apps.auths_api.urls' from '/home/roger/proyectos/learning/learning/ioteca_service/ioteca_service_apps/auths_api/urls.py'> (None:None) ^api/auths/>], [<RegexURLResolver <module 'ioteca_service_apps.dper.urls' from '/home/roger/proyectos/learning/learning/ioteca_service/ioteca_service_apps/dper/urls.py'> (None:None) ^api/dper/>]]}

During handling of the above exception, another exception occurred:

Traceback (most recent call last):
  File "/home/roger/.virtualenvs/learning/lib/python3.5/site-packages/django/template/base.py", line 883, in _resolve_lookup
    current = current[bit]
TypeError: 'RegexURLResolver' object is not subscriptable

During handling of the above exception, another exception occurred:

Traceback (most recent call last):
  File "/home/roger/.virtualenvs/learning/lib/python3.5/site-packages/django/template/base.py", line 891, in _resolve_lookup
    current = getattr(current, bit)
AttributeError: 'RegexURLResolver' object has no attribute 'name'

During handling of the above exception, another exception occurred:

Traceback (most recent call last):
  File "/home/roger/.virtualenvs/learning/lib/python3.5/site-packages/django/template/base.py", line 898, in _resolve_lookup
    current = current[int(bit)]
ValueError: invalid literal for int() with base 10: 'name'

During handling of the above exception, another exception occurred:

Traceback (most recent call last):
  File "/home/roger/.virtualenvs/learning/lib/python3.5/site-packages/django/template/base.py", line 905, in _resolve_lookup
    (bit, current))  # missing attribute
django.template.base.VariableDoesNotExist: Failed lookup for key [name] in "<RegexURLResolver <module 'rest_framework.urls' from '/home/roger/.virtualenvs/learning/lib/python3.5/site-packages/rest_framework/urls.py'> (rest_framework:rest_framework) ^api-auth/>"
[2016-12-12 22:34:29] DEBUG [django.template:927] Exception while resolving variable 'name' in template 'unknown'.
Traceback (most recent call last):
  File "/home/roger/.virtualenvs/learning/lib/python3.5/site-packages/django/core/handlers/base.py", line 134, in get_response
    resolver_match = resolver.resolve(request.path_info)
  File "/home/roger/.virtualenvs/learning/lib/python3.5/site-packages/django/core/urlresolvers.py", line 404, in resolve
    raise Resolver404({'tried': tried, 'path': new_path})
django.core.urlresolvers.Resolver404: {'path': 'favicon.ico', 'tried': [[<RegexURLResolver <RegexURLPattern list> (admin:admin) ^admin/>], [<RegexURLResolver <module 'django.contrib.admindocs.urls' from '/home/roger/.virtualenvs/learning/lib/python3.5/site-packages/django/contrib/admindocs/urls.py'> (None:None) ^admin/doc/>], [<RegexURLResolver <module 'rest_framework.urls' from '/home/roger/.virtualenvs/learning/lib/python3.5/site-packages/rest_framework/urls.py'> (rest_framework:rest_framework) ^api-auth/>], [<RegexURLResolver <module 'oauth2_provider.urls' from '/home/roger/.virtualenvs/learning/lib/python3.5/site-packages/oauth2_provider/urls.py'> (None:oauth2_provider) ^o/>], [<RegexURLResolver <module 'ioteca_service_apps.auths_api.urls' from '/home/roger/proyectos/learning/learning/ioteca_service/ioteca_service_apps/auths_api/urls.py'> (None:None) ^api/auths/>], [<RegexURLResolver <module 'ioteca_service_apps.dper.urls' from '/home/roger/proyectos/learning/learning/ioteca_service/ioteca_service_apps/dper/urls.py'> (None:None) ^api/dper/>]]}

During handling of the above exception, another exception occurred:

Traceback (most recent call last):
  File "/home/roger/.virtualenvs/learning/lib/python3.5/site-packages/django/template/base.py", line 883, in _resolve_lookup
    current = current[bit]
TypeError: 'RegexURLResolver' object is not subscriptable

During handling of the above exception, another exception occurred:

Traceback (most recent call last):
  File "/home/roger/.virtualenvs/learning/lib/python3.5/site-packages/django/template/base.py", line 891, in _resolve_lookup
    current = getattr(current, bit)
AttributeError: 'RegexURLResolver' object has no attribute 'name'

During handling of the above exception, another exception occurred:

Traceback (most recent call last):
  File "/home/roger/.virtualenvs/learning/lib/python3.5/site-packages/django/template/base.py", line 898, in _resolve_lookup
    current = current[int(bit)]
ValueError: invalid literal for int() with base 10: 'name'

During handling of the above exception, another exception occurred:

Traceback (most recent call last):
  File "/home/roger/.virtualenvs/learning/lib/python3.5/site-packages/django/template/base.py", line 905, in _resolve_lookup
    (bit, current))  # missing attribute
django.template.base.VariableDoesNotExist: Failed lookup for key [name] in "<RegexURLResolver <module 'oauth2_provider.urls' from '/home/roger/.virtualenvs/learning/lib/python3.5/site-packages/oauth2_provider/urls.py'> (None:oauth2_provider) ^o/>"
[2016-12-12 22:34:29] DEBUG [django.template:927] Exception while resolving variable 'name' in template 'unknown'.
Traceback (most recent call last):
  File "/home/roger/.virtualenvs/learning/lib/python3.5/site-packages/django/core/handlers/base.py", line 134, in get_response
    resolver_match = resolver.resolve(request.path_info)
  File "/home/roger/.virtualenvs/learning/lib/python3.5/site-packages/django/core/urlresolvers.py", line 404, in resolve
    raise Resolver404({'tried': tried, 'path': new_path})
django.core.urlresolvers.Resolver404: {'path': 'favicon.ico', 'tried': [[<RegexURLResolver <RegexURLPattern list> (admin:admin) ^admin/>], [<RegexURLResolver <module 'django.contrib.admindocs.urls' from '/home/roger/.virtualenvs/learning/lib/python3.5/site-packages/django/contrib/admindocs/urls.py'> (None:None) ^admin/doc/>], [<RegexURLResolver <module 'rest_framework.urls' from '/home/roger/.virtualenvs/learning/lib/python3.5/site-packages/rest_framework/urls.py'> (rest_framework:rest_framework) ^api-auth/>], [<RegexURLResolver <module 'oauth2_provider.urls' from '/home/roger/.virtualenvs/learning/lib/python3.5/site-packages/oauth2_provider/urls.py'> (None:oauth2_provider) ^o/>], [<RegexURLResolver <module 'ioteca_service_apps.auths_api.urls' from '/home/roger/proyectos/learning/learning/ioteca_service/ioteca_service_apps/auths_api/urls.py'> (None:None) ^api/auths/>], [<RegexURLResolver <module 'ioteca_service_apps.dper.urls' from '/home/roger/proyectos/learning/learning/ioteca_service/ioteca_service_apps/dper/urls.py'> (None:None) ^api/dper/>]]}

During handling of the above exception, another exception occurred:

Traceback (most recent call last):
  File "/home/roger/.virtualenvs/learning/lib/python3.5/site-packages/django/template/base.py", line 883, in _resolve_lookup
    current = current[bit]
TypeError: 'RegexURLResolver' object is not subscriptable

During handling of the above exception, another exception occurred:

Traceback (most recent call last):
  File "/home/roger/.virtualenvs/learning/lib/python3.5/site-packages/django/template/base.py", line 891, in _resolve_lookup
    current = getattr(current, bit)
AttributeError: 'RegexURLResolver' object has no attribute 'name'

During handling of the above exception, another exception occurred:

Traceback (most recent call last):
  File "/home/roger/.virtualenvs/learning/lib/python3.5/site-packages/django/template/base.py", line 898, in _resolve_lookup
    current = current[int(bit)]
ValueError: invalid literal for int() with base 10: 'name'

During handling of the above exception, another exception occurred:

Traceback (most recent call last):
  File "/home/roger/.virtualenvs/learning/lib/python3.5/site-packages/django/template/base.py", line 905, in _resolve_lookup
    (bit, current))  # missing attribute
django.template.base.VariableDoesNotExist: Failed lookup for key [name] in "<RegexURLResolver <module 'ioteca_service_apps.auths_api.urls' from '/home/roger/proyectos/learning/learning/ioteca_service/ioteca_service_apps/auths_api/urls.py'> (None:None) ^api/auths/>"
[2016-12-12 22:34:29] DEBUG [django.template:927] Exception while resolving variable 'name' in template 'unknown'.
Traceback (most recent call last):
  File "/home/roger/.virtualenvs/learning/lib/python3.5/site-packages/django/core/handlers/base.py", line 134, in get_response
    resolver_match = resolver.resolve(request.path_info)
  File "/home/roger/.virtualenvs/learning/lib/python3.5/site-packages/django/core/urlresolvers.py", line 404, in resolve
    raise Resolver404({'tried': tried, 'path': new_path})
django.core.urlresolvers.Resolver404: {'path': 'favicon.ico', 'tried': [[<RegexURLResolver <RegexURLPattern list> (admin:admin) ^admin/>], [<RegexURLResolver <module 'django.contrib.admindocs.urls' from '/home/roger/.virtualenvs/learning/lib/python3.5/site-packages/django/contrib/admindocs/urls.py'> (None:None) ^admin/doc/>], [<RegexURLResolver <module 'rest_framework.urls' from '/home/roger/.virtualenvs/learning/lib/python3.5/site-packages/rest_framework/urls.py'> (rest_framework:rest_framework) ^api-auth/>], [<RegexURLResolver <module 'oauth2_provider.urls' from '/home/roger/.virtualenvs/learning/lib/python3.5/site-packages/oauth2_provider/urls.py'> (None:oauth2_provider) ^o/>], [<RegexURLResolver <module 'ioteca_service_apps.auths_api.urls' from '/home/roger/proyectos/learning/learning/ioteca_service/ioteca_service_apps/auths_api/urls.py'> (None:None) ^api/auths/>], [<RegexURLResolver <module 'ioteca_service_apps.dper.urls' from '/home/roger/proyectos/learning/learning/ioteca_service/ioteca_service_apps/dper/urls.py'> (None:None) ^api/dper/>]]}

During handling of the above exception, another exception occurred:

Traceback (most recent call last):
  File "/home/roger/.virtualenvs/learning/lib/python3.5/site-packages/django/template/base.py", line 883, in _resolve_lookup
    current = current[bit]
TypeError: 'RegexURLResolver' object is not subscriptable

During handling of the above exception, another exception occurred:

Traceback (most recent call last):
  File "/home/roger/.virtualenvs/learning/lib/python3.5/site-packages/django/template/base.py", line 891, in _resolve_lookup
    current = getattr(current, bit)
AttributeError: 'RegexURLResolver' object has no attribute 'name'

During handling of the above exception, another exception occurred:

Traceback (most recent call last):
  File "/home/roger/.virtualenvs/learning/lib/python3.5/site-packages/django/template/base.py", line 898, in _resolve_lookup
    current = current[int(bit)]
ValueError: invalid literal for int() with base 10: 'name'

During handling of the above exception, another exception occurred:

Traceback (most recent call last):
  File "/home/roger/.virtualenvs/learning/lib/python3.5/site-packages/django/template/base.py", line 905, in _resolve_lookup
    (bit, current))  # missing attribute
django.template.base.VariableDoesNotExist: Failed lookup for key [name] in "<RegexURLResolver <module 'ioteca_service_apps.dper.urls' from '/home/roger/proyectos/learning/learning/ioteca_service/ioteca_service_apps/dper/urls.py'> (None:None) ^api/dper/>"
[2016-12-12 22:34:36] DEBUG [django.db.backends:89] (0.002) SELECT "auths_user"."password", "auths_user"."last_login", "auths_user"."is_superuser", "auths_user"."username", "auths_user"."first_name", "auths_user"."last_name", "auths_user"."email", "auths_user"."is_staff", "auths_user"."is_active", "auths_user"."date_joined", "auths_user"."id", "auths_user"."last_hierarchy_id", "auths_user"."last_module_id", "auths_user"."person_id", "auths_user"."updated_at", "auths_user"."registered_by" FROM "auths_user" WHERE "auths_user"."username" = 'roger'; args=('roger',)
[2016-12-12 22:34:36] DEBUG [django.template:927] Exception while resolving variable 'is_popup' in template 'admin/login.html'.
Traceback (most recent call last):
  File "/home/roger/.virtualenvs/learning/lib/python3.5/site-packages/django/template/base.py", line 883, in _resolve_lookup
    current = current[bit]
  File "/home/roger/.virtualenvs/learning/lib/python3.5/site-packages/django/template/context.py", line 77, in __getitem__
    raise KeyError(key)
KeyError: 'is_popup'

During handling of the above exception, another exception occurred:

Traceback (most recent call last):
  File "/home/roger/.virtualenvs/learning/lib/python3.5/site-packages/django/template/base.py", line 889, in _resolve_lookup
    if isinstance(current, BaseContext) and getattr(type(current), bit):
AttributeError: type object 'RequestContext' has no attribute 'is_popup'

During handling of the above exception, another exception occurred:

Traceback (most recent call last):
  File "/home/roger/.virtualenvs/learning/lib/python3.5/site-packages/django/template/base.py", line 898, in _resolve_lookup
    current = current[int(bit)]
ValueError: invalid literal for int() with base 10: 'is_popup'

During handling of the above exception, another exception occurred:

Traceback (most recent call last):
  File "/home/roger/.virtualenvs/learning/lib/python3.5/site-packages/django/template/base.py", line 905, in _resolve_lookup
    (bit, current))  # missing attribute
django.template.base.VariableDoesNotExist: Failed lookup for key [is_popup] in "[{'False': False, 'True': True, 'None': None}, {'csrf_token': <SimpleLazyObject: <function csrf.<locals>._get_val at 0x7f7aafa78bf8>>, 'messages': <django.contrib.messages.storage.fallback.FallbackStorage object at 0x7f7aaea33b38>, 'user': <SimpleLazyObject: <django.contrib.auth.models.AnonymousUser object at 0x7f7aaea489b0>>, 'DEFAULT_MESSAGE_LEVELS': {'DEBUG': 10, 'SUCCESS': 25, 'WARNING': 30, 'ERROR': 40, 'INFO': 20}, 'request': <WSGIRequest: POST '/admin/login/?next=/admin/'>, 'perms': <django.contrib.auth.context_processors.PermWrapper object at 0x7f7aad7ae860>}, {}, {'site_title': <django.utils.functional.lazy.<locals>.__proxy__ object at 0x7f7ab5bc25c0>, 'title': 'Log in', 'LANGUAGE_CODE': 'en-us', 'next': '/admin/', 'has_permission': False, 'site_url': '/', 'site_header': <django.utils.functional.lazy.<locals>.__proxy__ object at 0x7f7ab5b5f470>, 'available_apps': [], 'app_path': '/admin/login/?next=/admin/', 'LANGUAGE_BIDI': False, 'site': <django.contrib.sites.requests.RequestSite object at 0x7f7ab5adfb00>, 'form': <AdminAuthenticationForm bound=True, valid=False, fields=(username;password)>, 'site_name': 'localhost:9001'}]"
[2016-12-12 22:34:36] DEBUG [django.template:927] Exception while resolving variable 'is_popup' in template 'admin/login.html'.
Traceback (most recent call last):
  File "/home/roger/.virtualenvs/learning/lib/python3.5/site-packages/django/template/base.py", line 883, in _resolve_lookup
    current = current[bit]
  File "/home/roger/.virtualenvs/learning/lib/python3.5/site-packages/django/template/context.py", line 77, in __getitem__
    raise KeyError(key)
KeyError: 'is_popup'

During handling of the above exception, another exception occurred:

Traceback (most recent call last):
  File "/home/roger/.virtualenvs/learning/lib/python3.5/site-packages/django/template/base.py", line 889, in _resolve_lookup
    if isinstance(current, BaseContext) and getattr(type(current), bit):
AttributeError: type object 'RequestContext' has no attribute 'is_popup'

During handling of the above exception, another exception occurred:

Traceback (most recent call last):
  File "/home/roger/.virtualenvs/learning/lib/python3.5/site-packages/django/template/base.py", line 898, in _resolve_lookup
    current = current[int(bit)]
ValueError: invalid literal for int() with base 10: 'is_popup'

During handling of the above exception, another exception occurred:

Traceback (most recent call last):
  File "/home/roger/.virtualenvs/learning/lib/python3.5/site-packages/django/template/base.py", line 905, in _resolve_lookup
    (bit, current))  # missing attribute
django.template.base.VariableDoesNotExist: Failed lookup for key [is_popup] in "[{'False': False, 'True': True, 'None': None}, {'csrf_token': <SimpleLazyObject: <function csrf.<locals>._get_val at 0x7f7aafa78bf8>>, 'messages': <django.contrib.messages.storage.fallback.FallbackStorage object at 0x7f7aaea33b38>, 'user': <SimpleLazyObject: <django.contrib.auth.models.AnonymousUser object at 0x7f7aaea489b0>>, 'DEFAULT_MESSAGE_LEVELS': {'DEBUG': 10, 'SUCCESS': 25, 'WARNING': 30, 'ERROR': 40, 'INFO': 20}, 'request': <WSGIRequest: POST '/admin/login/?next=/admin/'>, 'perms': <django.contrib.auth.context_processors.PermWrapper object at 0x7f7aad7ae860>}, {}, {'site_title': <django.utils.functional.lazy.<locals>.__proxy__ object at 0x7f7ab5bc25c0>, 'title': 'Log in', 'LANGUAGE_CODE': 'en-us', 'next': '/admin/', 'has_permission': False, 'site_url': '/', 'site_header': <django.utils.functional.lazy.<locals>.__proxy__ object at 0x7f7ab5b5f470>, 'available_apps': [], 'app_path': '/admin/login/?next=/admin/', 'LANGUAGE_BIDI': False, 'site': <django.contrib.sites.requests.RequestSite object at 0x7f7ab5adfb00>, 'form': <AdminAuthenticationForm bound=True, valid=False, fields=(username;password)>, 'site_name': 'localhost:9001'}]"
[2016-12-12 22:34:53] DEBUG [django.db.backends:89] (0.001) SELECT "auths_user"."password", "auths_user"."last_login", "auths_user"."is_superuser", "auths_user"."username", "auths_user"."first_name", "auths_user"."last_name", "auths_user"."email", "auths_user"."is_staff", "auths_user"."is_active", "auths_user"."date_joined", "auths_user"."id", "auths_user"."last_hierarchy_id", "auths_user"."last_module_id", "auths_user"."person_id", "auths_user"."updated_at", "auths_user"."registered_by" FROM "auths_user" WHERE "auths_user"."username" = 'roger'; args=('roger',)
[2016-12-12 22:34:57] DEBUG [django.db.backends:89] (0.000) SELECT "auths_user"."password", "auths_user"."last_login", "auths_user"."is_superuser", "auths_user"."username", "auths_user"."first_name", "auths_user"."last_name", "auths_user"."email", "auths_user"."is_staff", "auths_user"."is_active", "auths_user"."date_joined", "auths_user"."id", "auths_user"."last_hierarchy_id", "auths_user"."last_module_id", "auths_user"."person_id", "auths_user"."updated_at", "auths_user"."registered_by" FROM "auths_user" WHERE "auths_user"."username" = 'r'; args=('r',)
[2016-12-12 22:35:10] DEBUG [django.db.backends:89] (0.000) BEGIN; args=None
[2016-12-12 22:35:10] DEBUG [django.db.backends:89] (0.000) UPDATE "auths_user" SET "password" = 'pbkdf2_sha256$24000$eTt0aPCf7yOH$nmm9YvlrJI761iqvLgcPBJGY0S07oAu054OAXoLg0Ns=', "last_login" = NULL, "is_superuser" = 1, "username" = 'r', "first_name" = '', "last_name" = '', "email" = '', "is_staff" = 1, "is_active" = 1, "date_joined" = '2016-12-12 22:35:10.320949', "last_hierarchy_id" = NULL, "last_module_id" = NULL, "person_id" = NULL, "updated_at" = '2016-12-12 22:35:10.367127', "registered_by" = NULL WHERE "auths_user"."id" = '2f22885837cb451cb36a4ff40a7a35dc'; args=('pbkdf2_sha256$24000$eTt0aPCf7yOH$nmm9YvlrJI761iqvLgcPBJGY0S07oAu054OAXoLg0Ns=', True, 'r', '', '', '', True, True, '2016-12-12 22:35:10.320949', '2016-12-12 22:35:10.367127', '2f22885837cb451cb36a4ff40a7a35dc')
[2016-12-12 22:35:10] DEBUG [django.db.backends:89] (0.000) INSERT INTO "auths_user" ("password", "last_login", "is_superuser", "username", "first_name", "last_name", "email", "is_staff", "is_active", "date_joined", "id", "last_hierarchy_id", "last_module_id", "person_id", "updated_at", "registered_by") SELECT 'pbkdf2_sha256$24000$eTt0aPCf7yOH$nmm9YvlrJI761iqvLgcPBJGY0S07oAu054OAXoLg0Ns=', NULL, 1, 'r', '', '', '', 1, 1, '2016-12-12 22:35:10.320949', '2f22885837cb451cb36a4ff40a7a35dc', NULL, NULL, NULL, '2016-12-12 22:35:10.368793', NULL; args=('pbkdf2_sha256$24000$eTt0aPCf7yOH$nmm9YvlrJI761iqvLgcPBJGY0S07oAu054OAXoLg0Ns=', None, True, 'r', '', '', '', True, True, '2016-12-12 22:35:10.320949', '2f22885837cb451cb36a4ff40a7a35dc', None, None, None, '2016-12-12 22:35:10.368793', None)
[2016-12-12 22:35:16] DEBUG [django.db.backends:89] (0.001) 
            SELECT name, type FROM sqlite_master
            WHERE type in ('table', 'view') AND NOT name='sqlite_sequence'
            ORDER BY name; args=None
[2016-12-12 22:35:16] DEBUG [django.db.backends:89] (0.000) SELECT "django_migrations"."app", "django_migrations"."name" FROM "django_migrations"; args=()
[2016-12-12 22:35:23] DEBUG [django.db.backends:89] (0.002) SELECT "auths_user"."password", "auths_user"."last_login", "auths_user"."is_superuser", "auths_user"."username", "auths_user"."first_name", "auths_user"."last_name", "auths_user"."email", "auths_user"."is_staff", "auths_user"."is_active", "auths_user"."date_joined", "auths_user"."id", "auths_user"."last_hierarchy_id", "auths_user"."last_module_id", "auths_user"."person_id", "auths_user"."updated_at", "auths_user"."registered_by" FROM "auths_user" WHERE "auths_user"."username" = 'r'; args=('r',)
[2016-12-12 22:35:23] DEBUG [django.db.backends:89] (0.000) SELECT (1) AS "a" FROM "django_session" WHERE "django_session"."session_key" = '0d4vywe072g73nddp7eae6gdw2w2fivo' LIMIT 1; args=('0d4vywe072g73nddp7eae6gdw2w2fivo',)
[2016-12-12 22:35:23] DEBUG [django.db.backends:89] (0.000) BEGIN; args=None
[2016-12-12 22:35:23] DEBUG [django.db.backends:89] (0.000) INSERT INTO "django_session" ("session_key", "session_data", "expire_date") SELECT '0d4vywe072g73nddp7eae6gdw2w2fivo', 'MWM0OGIyODQ4NzI4MzRhZjAyMjIxNmY1YzZlNzUwYmUzNTU2OWFjMTp7fQ==', '2016-12-26 22:35:23.075742'; args=('0d4vywe072g73nddp7eae6gdw2w2fivo', 'MWM0OGIyODQ4NzI4MzRhZjAyMjIxNmY1YzZlNzUwYmUzNTU2OWFjMTp7fQ==', '2016-12-26 22:35:23.075742')
[2016-12-12 22:35:23] DEBUG [django.db.backends:89] (0.000) SELECT "django_session"."session_key", "django_session"."session_data", "django_session"."expire_date" FROM "django_session" WHERE "django_session"."session_key" = '0d4vywe072g73nddp7eae6gdw2w2fivo'; args=('0d4vywe072g73nddp7eae6gdw2w2fivo',)
[2016-12-12 22:35:23] DEBUG [django.db.backends:89] (0.000) BEGIN; args=None
[2016-12-12 22:35:23] DEBUG [django.db.backends:89] (0.000) DELETE FROM "django_session" WHERE "django_session"."session_key" IN ('0d4vywe072g73nddp7eae6gdw2w2fivo'); args=('0d4vywe072g73nddp7eae6gdw2w2fivo',)
[2016-12-12 22:35:23] DEBUG [django.db.backends:89] (0.000) BEGIN; args=None
[2016-12-12 22:35:23] DEBUG [django.db.backends:89] (0.000) UPDATE "auths_user" SET "last_login" = '2016-12-12 22:35:23.282159' WHERE "auths_user"."id" = '2f22885837cb451cb36a4ff40a7a35dc'; args=('2016-12-12 22:35:23.282159', '2f22885837cb451cb36a4ff40a7a35dc')
[2016-12-12 22:35:23] DEBUG [django.db.backends:89] (0.000) BEGIN; args=None
[2016-12-12 22:35:23] DEBUG [django.db.backends:89] (0.000) UPDATE "django_session" SET "session_data" = 'MjU3ZjhmMTYzZTgwYzhlY2I1ZjY2ODJiOWE1YmQ3ZDliYWY3N2MxYzp7Il9hdXRoX3VzZXJfaWQiOiIyZjIyODg1OC0zN2NiLTQ1MWMtYjM2YS00ZmY0MGE3YTM1ZGMiLCJfYXV0aF91c2VyX2hhc2giOiJhOGE0NjMxZjkxODU0MTY4MjA3OGFkZjQ3OTAzYmM2MTcwNDNkYTBlIiwiX2F1dGhfdXNlcl9iYWNrZW5kIjoiZGphbmdvLmNvbnRyaWIuYXV0aC5iYWNrZW5kcy5Nb2RlbEJhY2tlbmQifQ==', "expire_date" = '2016-12-26 22:35:23.351356' WHERE "django_session"."session_key" = '0d4vywe072g73nddp7eae6gdw2w2fivo'; args=('MjU3ZjhmMTYzZTgwYzhlY2I1ZjY2ODJiOWE1YmQ3ZDliYWY3N2MxYzp7Il9hdXRoX3VzZXJfaWQiOiIyZjIyODg1OC0zN2NiLTQ1MWMtYjM2YS00ZmY0MGE3YTM1ZGMiLCJfYXV0aF91c2VyX2hhc2giOiJhOGE0NjMxZjkxODU0MTY4MjA3OGFkZjQ3OTAzYmM2MTcwNDNkYTBlIiwiX2F1dGhfdXNlcl9iYWNrZW5kIjoiZGphbmdvLmNvbnRyaWIuYXV0aC5iYWNrZW5kcy5Nb2RlbEJhY2tlbmQifQ==', '2016-12-26 22:35:23.351356', '0d4vywe072g73nddp7eae6gdw2w2fivo')
[2016-12-12 22:35:23] DEBUG [django.db.backends:89] (0.000) INSERT INTO "django_session" ("session_key", "session_data", "expire_date") SELECT '0d4vywe072g73nddp7eae6gdw2w2fivo', 'MjU3ZjhmMTYzZTgwYzhlY2I1ZjY2ODJiOWE1YmQ3ZDliYWY3N2MxYzp7Il9hdXRoX3VzZXJfaWQiOiIyZjIyODg1OC0zN2NiLTQ1MWMtYjM2YS00ZmY0MGE3YTM1ZGMiLCJfYXV0aF91c2VyX2hhc2giOiJhOGE0NjMxZjkxODU0MTY4MjA3OGFkZjQ3OTAzYmM2MTcwNDNkYTBlIiwiX2F1dGhfdXNlcl9iYWNrZW5kIjoiZGphbmdvLmNvbnRyaWIuYXV0aC5iYWNrZW5kcy5Nb2RlbEJhY2tlbmQifQ==', '2016-12-26 22:35:23.351356'; args=('0d4vywe072g73nddp7eae6gdw2w2fivo', 'MjU3ZjhmMTYzZTgwYzhlY2I1ZjY2ODJiOWE1YmQ3ZDliYWY3N2MxYzp7Il9hdXRoX3VzZXJfaWQiOiIyZjIyODg1OC0zN2NiLTQ1MWMtYjM2YS00ZmY0MGE3YTM1ZGMiLCJfYXV0aF91c2VyX2hhc2giOiJhOGE0NjMxZjkxODU0MTY4MjA3OGFkZjQ3OTAzYmM2MTcwNDNkYTBlIiwiX2F1dGhfdXNlcl9iYWNrZW5kIjoiZGphbmdvLmNvbnRyaWIuYXV0aC5iYWNrZW5kcy5Nb2RlbEJhY2tlbmQifQ==', '2016-12-26 22:35:23.351356')
[2016-12-12 22:35:23] DEBUG [django.db.backends:89] (0.002) SELECT "django_session"."session_key", "django_session"."session_data", "django_session"."expire_date" FROM "django_session" WHERE ("django_session"."session_key" = '0d4vywe072g73nddp7eae6gdw2w2fivo' AND "django_session"."expire_date" > '2016-12-12 22:35:23.477108'); args=('0d4vywe072g73nddp7eae6gdw2w2fivo', '2016-12-12 22:35:23.477108')
[2016-12-12 22:35:23] DEBUG [django.db.backends:89] (0.000) SELECT "auths_user"."password", "auths_user"."last_login", "auths_user"."is_superuser", "auths_user"."username", "auths_user"."first_name", "auths_user"."last_name", "auths_user"."email", "auths_user"."is_staff", "auths_user"."is_active", "auths_user"."date_joined", "auths_user"."id", "auths_user"."last_hierarchy_id", "auths_user"."last_module_id", "auths_user"."person_id", "auths_user"."updated_at", "auths_user"."registered_by" FROM "auths_user" WHERE "auths_user"."id" = '2f22885837cb451cb36a4ff40a7a35dc'; args=('2f22885837cb451cb36a4ff40a7a35dc',)
[2016-12-12 22:35:23] DEBUG [django.template:927] Exception while resolving variable 'is_popup' in template 'admin/index.html'.
Traceback (most recent call last):
  File "/home/roger/.virtualenvs/learning/lib/python3.5/site-packages/django/template/base.py", line 883, in _resolve_lookup
    current = current[bit]
  File "/home/roger/.virtualenvs/learning/lib/python3.5/site-packages/django/template/context.py", line 77, in __getitem__
    raise KeyError(key)
KeyError: 'is_popup'

During handling of the above exception, another exception occurred:

Traceback (most recent call last):
  File "/home/roger/.virtualenvs/learning/lib/python3.5/site-packages/django/template/base.py", line 889, in _resolve_lookup
    if isinstance(current, BaseContext) and getattr(type(current), bit):
AttributeError: type object 'RequestContext' has no attribute 'is_popup'

During handling of the above exception, another exception occurred:

Traceback (most recent call last):
  File "/home/roger/.virtualenvs/learning/lib/python3.5/site-packages/django/template/base.py", line 898, in _resolve_lookup
    current = current[int(bit)]
ValueError: invalid literal for int() with base 10: 'is_popup'

During handling of the above exception, another exception occurred:

Traceback (most recent call last):
  File "/home/roger/.virtualenvs/learning/lib/python3.5/site-packages/django/template/base.py", line 905, in _resolve_lookup
    (bit, current))  # missing attribute
django.template.base.VariableDoesNotExist: Failed lookup for key [is_popup] in "[{'False': False, 'None': None, 'True': True}, {'DEFAULT_MESSAGE_LEVELS': {'DEBUG': 10, 'WARNING': 30, 'ERROR': 40, 'INFO': 20, 'SUCCESS': 25}, 'user': <SimpleLazyObject: <User: r>>, 'messages': <django.contrib.messages.storage.fallback.FallbackStorage object at 0x7fa53023c630>, 'perms': <django.contrib.auth.context_processors.PermWrapper object at 0x7fa52b7bdf28>, 'request': <WSGIRequest: GET '/admin/'>, 'csrf_token': <SimpleLazyObject: <function csrf.<locals>._get_val at 0x7fa5302a4d08>>}, {}, {'site_title': <django.utils.functional.lazy.<locals>.__proxy__ object at 0x7fa532326160>, 'available_apps': [{'models': [{'add_url': '/admin/auth/group/add/', 'object_name': 'Group', 'name': <django.utils.functional.lazy.<locals>.__proxy__ object at 0x7fa53023c6a0>, 'perms': {'change': True, 'add': True, 'delete': True}, 'admin_url': '/admin/auth/group/'}, {'add_url': '/admin/auth/permission/add/', 'object_name': 'Permission', 'name': <django.utils.functional.lazy.<locals>.__proxy__ object at 0x7fa5302945c0>, 'perms': {'change': True, 'add': True, 'delete': True}, 'admin_url': '/admin/auth/permission/'}], 'app_label': 'auth', 'has_module_perms': True, 'name': <django.utils.functional.lazy.<locals>.__proxy__ object at 0x7fa532333f60>, 'app_url': '/admin/auth/'}, {'models': [{'add_url': '/admin/auths/hierarchytype/add/', 'object_name': 'HierarchyType', 'name': <django.utils.functional.lazy.<locals>.__proxy__ object at 0x7fa530294390>, 'perms': {'change': True, 'add': True, 'delete': True}, 'admin_url': '/admin/auths/hierarchytype/'}, {'add_url': '/admin/auths/hierarchy/add/', 'object_name': 'Hierarchy', 'name': <django.utils.functional.lazy.<locals>.__proxy__ object at 0x7fa530294898>, 'perms': {'change': True, 'add': True, 'delete': True}, 'admin_url': '/admin/auths/hierarchy/'}, {'add_url': '/admin/auths/menu/add/', 'object_name': 'Menu', 'name': <django.utils.functional.lazy.<locals>.__proxy__ object at 0x7fa53023cd68>, 'perms': {'change': True, 'add': True, 'delete': True}, 'admin_url': '/admin/auths/menu/'}, {'add_url': '/admin/auths/person/add/', 'object_name': 'Person', 'name': <django.utils.functional.lazy.<locals>.__proxy__ object at 0x7fa530294470>, 'perms': {'change': True, 'add': True, 'delete': True}, 'admin_url': '/admin/auths/person/'}, {'add_url': '/admin/auths/userhierarchygroup/add/', 'object_name': 'UserHierarchyGroup', 'name': <django.utils.functional.lazy.<locals>.__proxy__ object at 0x7fa530294518>, 'perms': {'change': True, 'add': True, 'delete': True}, 'admin_url': '/admin/auths/userhierarchygroup/'}, {'add_url': '/admin/auths/userhierarchypermission/add/', 'object_name': 'UserHierarchyPermission', 'name': <django.utils.functional.lazy.<locals>.__proxy__ object at 0x7fa53052d588>, 'perms': {'change': True, 'add': True, 'delete': True}, 'admin_url': '/admin/auths/userhierarchypermission/'}, {'add_url': '/admin/auths/user/add/', 'object_name': 'User', 'name': <django.utils.functional.lazy.<locals>.__proxy__ object at 0x7fa530525f60>, 'perms': {'change': True, 'add': True, 'delete': True}, 'admin_url': '/admin/auths/user/'}], 'app_label': 'auths', 'has_module_perms': True, 'name': 'Auths', 'app_url': '/admin/auths/'}, {'models': [{'add_url': '/admin/contenttypes/contenttype/add/', 'object_name': 'ContentType', 'name': <django.utils.functional.lazy.<locals>.__proxy__ object at 0x7fa5309da390>, 'perms': {'change': True, 'add': True, 'delete': True}, 'admin_url': '/admin/contenttypes/contenttype/'}], 'app_label': 'contenttypes', 'has_module_perms': True, 'name': <django.utils.functional.lazy.<locals>.__proxy__ object at 0x7fa53233b710>, 'app_url': '/admin/contenttypes/'}, {'models': [{'add_url': '/admin/oauth2_provider/accesstoken/add/', 'object_name': 'AccessToken', 'name': <django.utils.functional.lazy.<locals>.__proxy__ object at 0x7fa5302943c8>, 'perms': {'change': True, 'add': True, 'delete': True}, 'admin_url': '/admin/oauth2_provider/accesstoken/'}, {'add_url': '/admin/oauth2_provider/application/add/', 'object_name': 'Application', 'name': <django.utils.functional.lazy.<locals>.__proxy__ object at 0x7fa530294438>, 'perms': {'change': True, 'add': True, 'delete': True}, 'admin_url': '/admin/oauth2_provider/application/'}, {'add_url': '/admin/oauth2_provider/grant/add/', 'object_name': 'Grant', 'name': <django.utils.functional.lazy.<locals>.__proxy__ object at 0x7fa5309da710>, 'perms': {'change': True, 'add': True, 'delete': True}, 'admin_url': '/admin/oauth2_provider/grant/'}, {'add_url': '/admin/oauth2_provider/refreshtoken/add/', 'object_name': 'RefreshToken', 'name': <django.utils.functional.lazy.<locals>.__proxy__ object at 0x7fa530294c50>, 'perms': {'change': True, 'add': True, 'delete': True}, 'admin_url': '/admin/oauth2_provider/refreshtoken/'}], 'app_label': 'oauth2_provider', 'has_module_perms': True, 'name': 'Django OAuth Toolkit', 'app_url': '/admin/oauth2_provider/'}, {'models': [{'add_url': '/admin/dper/persona/add/', 'object_name': 'Persona', 'name': <django.utils.functional.lazy.<locals>.__proxy__ object at 0x7fa5302944a8>, 'perms': {'change': True, 'add': True, 'delete': True}, 'admin_url': '/admin/dper/persona/'}, {'add_url': '/admin/dper/profecion/add/', 'object_name': 'Profecion', 'name': <django.utils.functional.lazy.<locals>.__proxy__ object at 0x7fa53052d080>, 'perms': {'change': True, 'add': True, 'delete': True}, 'admin_url': '/admin/dper/profecion/'}], 'app_label': 'dper', 'has_module_perms': True, 'name': 'Dper', 'app_url': '/admin/dper/'}], 'app_list': [{'models': [{'add_url': '/admin/auth/group/add/', 'object_name': 'Group', 'name': <django.utils.functional.lazy.<locals>.__proxy__ object at 0x7fa53023cdd8>, 'perms': {'change': True, 'add': True, 'delete': True}, 'admin_url': '/admin/auth/group/'}, {'add_url': '/admin/auth/permission/add/', 'object_name': 'Permission', 'name': <django.utils.functional.lazy.<locals>.__proxy__ object at 0x7fa530288ef0>, 'perms': {'change': True, 'add': True, 'delete': True}, 'admin_url': '/admin/auth/permission/'}], 'app_label': 'auth', 'has_module_perms': True, 'name': <django.utils.functional.lazy.<locals>.__proxy__ object at 0x7fa532333f60>, 'app_url': '/admin/auth/'}, {'models': [{'add_url': '/admin/auths/hierarchytype/add/', 'object_name': 'HierarchyType', 'name': <django.utils.functional.lazy.<locals>.__proxy__ object at 0x7fa5302a2d68>, 'perms': {'change': True, 'add': True, 'delete': True}, 'admin_url': '/admin/auths/hierarchytype/'}, {'add_url': '/admin/auths/hierarchy/add/', 'object_name': 'Hierarchy', 'name': <django.utils.functional.lazy.<locals>.__proxy__ object at 0x7fa530288ac8>, 'perms': {'change': True, 'add': True, 'delete': True}, 'admin_url': '/admin/auths/hierarchy/'}, {'add_url': '/admin/auths/menu/add/', 'object_name': 'Menu', 'name': <django.utils.functional.lazy.<locals>.__proxy__ object at 0x7fa52b7c6c88>, 'perms': {'change': True, 'add': True, 'delete': True}, 'admin_url': '/admin/auths/menu/'}, {'add_url': '/admin/auths/person/add/', 'object_name': 'Person', 'name': <django.utils.functional.lazy.<locals>.__proxy__ object at 0x7fa5302a2748>, 'perms': {'change': True, 'add': True, 'delete': True}, 'admin_url': '/admin/auths/person/'}, {'add_url': '/admin/auths/userhierarchygroup/add/', 'object_name': 'UserHierarchyGroup', 'name': <django.utils.functional.lazy.<locals>.__proxy__ object at 0x7fa52b7c6d30>, 'perms': {'change': True, 'add': True, 'delete': True}, 'admin_url': '/admin/auths/userhierarchygroup/'}, {'add_url': '/admin/auths/userhierarchypermission/add/', 'object_name': 'UserHierarchyPermission', 'name': <django.utils.functional.lazy.<locals>.__proxy__ object at 0x7fa53023c940>, 'perms': {'change': True, 'add': True, 'delete': True}, 'admin_url': '/admin/auths/userhierarchypermission/'}, {'add_url': '/admin/auths/user/add/', 'object_name': 'User', 'name': <django.utils.functional.lazy.<locals>.__proxy__ object at 0x7fa53023c470>, 'perms': {'change': True, 'add': True, 'delete': True}, 'admin_url': '/admin/auths/user/'}], 'app_label': 'auths', 'has_module_perms': True, 'name': 'Auths', 'app_url': '/admin/auths/'}, {'models': [{'add_url': '/admin/contenttypes/contenttype/add/', 'object_name': 'ContentType', 'name': <django.utils.functional.lazy.<locals>.__proxy__ object at 0x7fa53023ccc0>, 'perms': {'change': True, 'add': True, 'delete': True}, 'admin_url': '/admin/contenttypes/contenttype/'}], 'app_label': 'contenttypes', 'has_module_perms': True, 'name': <django.utils.functional.lazy.<locals>.__proxy__ object at 0x7fa53233b710>, 'app_url': '/admin/contenttypes/'}, {'models': [{'add_url': '/admin/oauth2_provider/accesstoken/add/', 'object_name': 'AccessToken', 'name': <django.utils.functional.lazy.<locals>.__proxy__ object at 0x7fa5302a2cc0>, 'perms': {'change': True, 'add': True, 'delete': True}, 'admin_url': '/admin/oauth2_provider/accesstoken/'}, {'add_url': '/admin/oauth2_provider/application/add/', 'object_name': 'Application', 'name': <django.utils.functional.lazy.<locals>.__proxy__ object at 0x7fa530288f60>, 'perms': {'change': True, 'add': True, 'delete': True}, 'admin_url': '/admin/oauth2_provider/application/'}, {'add_url': '/admin/oauth2_provider/grant/add/', 'object_name': 'Grant', 'name': <django.utils.functional.lazy.<locals>.__proxy__ object at 0x7fa53023cf98>, 'perms': {'change': True, 'add': True, 'delete': True}, 'admin_url': '/admin/oauth2_provider/grant/'}, {'add_url': '/admin/oauth2_provider/refreshtoken/add/', 'object_name': 'RefreshToken', 'name': <django.utils.functional.lazy.<locals>.__proxy__ object at 0x7fa530288908>, 'perms': {'change': True, 'add': True, 'delete': True}, 'admin_url': '/admin/oauth2_provider/refreshtoken/'}], 'app_label': 'oauth2_provider', 'has_module_perms': True, 'name': 'Django OAuth Toolkit', 'app_url': '/admin/oauth2_provider/'}, {'models': [{'add_url': '/admin/dper/persona/add/', 'object_name': 'Persona', 'name': <django.utils.functional.lazy.<locals>.__proxy__ object at 0x7fa5302a27f0>, 'perms': {'change': True, 'add': True, 'delete': True}, 'admin_url': '/admin/dper/persona/'}, {'add_url': '/admin/dper/profecion/add/', 'object_name': 'Profecion', 'name': <django.utils.functional.lazy.<locals>.__proxy__ object at 0x7fa53023cac8>, 'perms': {'change': True, 'add': True, 'delete': True}, 'admin_url': '/admin/dper/profecion/'}], 'app_label': 'dper', 'has_module_perms': True, 'name': 'Dper', 'app_url': '/admin/dper/'}], 'LANGUAGE_BIDI': False, 'site_url': '/', 'site_header': <django.utils.functional.lazy.<locals>.__proxy__ object at 0x7fa532333438>, 'title': <django.utils.functional.lazy.<locals>.__proxy__ object at 0x7fa5323337f0>, 'has_permission': True, 'LANGUAGE_CODE': 'en-us'}]"
[2016-12-12 22:35:23] DEBUG [django.template:927] Exception while resolving variable 'is_popup' in template 'admin/index.html'.
Traceback (most recent call last):
  File "/home/roger/.virtualenvs/learning/lib/python3.5/site-packages/django/template/base.py", line 883, in _resolve_lookup
    current = current[bit]
  File "/home/roger/.virtualenvs/learning/lib/python3.5/site-packages/django/template/context.py", line 77, in __getitem__
    raise KeyError(key)
KeyError: 'is_popup'

During handling of the above exception, another exception occurred:

Traceback (most recent call last):
  File "/home/roger/.virtualenvs/learning/lib/python3.5/site-packages/django/template/base.py", line 889, in _resolve_lookup
    if isinstance(current, BaseContext) and getattr(type(current), bit):
AttributeError: type object 'RequestContext' has no attribute 'is_popup'

During handling of the above exception, another exception occurred:

Traceback (most recent call last):
  File "/home/roger/.virtualenvs/learning/lib/python3.5/site-packages/django/template/base.py", line 898, in _resolve_lookup
    current = current[int(bit)]
ValueError: invalid literal for int() with base 10: 'is_popup'

During handling of the above exception, another exception occurred:

Traceback (most recent call last):
  File "/home/roger/.virtualenvs/learning/lib/python3.5/site-packages/django/template/base.py", line 905, in _resolve_lookup
    (bit, current))  # missing attribute
django.template.base.VariableDoesNotExist: Failed lookup for key [is_popup] in "[{'False': False, 'None': None, 'True': True}, {'DEFAULT_MESSAGE_LEVELS': {'DEBUG': 10, 'WARNING': 30, 'ERROR': 40, 'INFO': 20, 'SUCCESS': 25}, 'user': <SimpleLazyObject: <User: r>>, 'messages': <django.contrib.messages.storage.fallback.FallbackStorage object at 0x7fa53023c630>, 'perms': <django.contrib.auth.context_processors.PermWrapper object at 0x7fa52b7bdf28>, 'request': <WSGIRequest: GET '/admin/'>, 'csrf_token': <SimpleLazyObject: <function csrf.<locals>._get_val at 0x7fa5302a4d08>>}, {}, {'site_title': <django.utils.functional.lazy.<locals>.__proxy__ object at 0x7fa532326160>, 'available_apps': [{'models': [{'add_url': '/admin/auth/group/add/', 'object_name': 'Group', 'name': <django.utils.functional.lazy.<locals>.__proxy__ object at 0x7fa53023c6a0>, 'perms': {'change': True, 'add': True, 'delete': True}, 'admin_url': '/admin/auth/group/'}, {'add_url': '/admin/auth/permission/add/', 'object_name': 'Permission', 'name': <django.utils.functional.lazy.<locals>.__proxy__ object at 0x7fa5302945c0>, 'perms': {'change': True, 'add': True, 'delete': True}, 'admin_url': '/admin/auth/permission/'}], 'app_label': 'auth', 'has_module_perms': True, 'name': <django.utils.functional.lazy.<locals>.__proxy__ object at 0x7fa532333f60>, 'app_url': '/admin/auth/'}, {'models': [{'add_url': '/admin/auths/hierarchytype/add/', 'object_name': 'HierarchyType', 'name': <django.utils.functional.lazy.<locals>.__proxy__ object at 0x7fa530294390>, 'perms': {'change': True, 'add': True, 'delete': True}, 'admin_url': '/admin/auths/hierarchytype/'}, {'add_url': '/admin/auths/hierarchy/add/', 'object_name': 'Hierarchy', 'name': <django.utils.functional.lazy.<locals>.__proxy__ object at 0x7fa530294898>, 'perms': {'change': True, 'add': True, 'delete': True}, 'admin_url': '/admin/auths/hierarchy/'}, {'add_url': '/admin/auths/menu/add/', 'object_name': 'Menu', 'name': <django.utils.functional.lazy.<locals>.__proxy__ object at 0x7fa53023cd68>, 'perms': {'change': True, 'add': True, 'delete': True}, 'admin_url': '/admin/auths/menu/'}, {'add_url': '/admin/auths/person/add/', 'object_name': 'Person', 'name': <django.utils.functional.lazy.<locals>.__proxy__ object at 0x7fa530294470>, 'perms': {'change': True, 'add': True, 'delete': True}, 'admin_url': '/admin/auths/person/'}, {'add_url': '/admin/auths/userhierarchygroup/add/', 'object_name': 'UserHierarchyGroup', 'name': <django.utils.functional.lazy.<locals>.__proxy__ object at 0x7fa530294518>, 'perms': {'change': True, 'add': True, 'delete': True}, 'admin_url': '/admin/auths/userhierarchygroup/'}, {'add_url': '/admin/auths/userhierarchypermission/add/', 'object_name': 'UserHierarchyPermission', 'name': <django.utils.functional.lazy.<locals>.__proxy__ object at 0x7fa53052d588>, 'perms': {'change': True, 'add': True, 'delete': True}, 'admin_url': '/admin/auths/userhierarchypermission/'}, {'add_url': '/admin/auths/user/add/', 'object_name': 'User', 'name': <django.utils.functional.lazy.<locals>.__proxy__ object at 0x7fa530525f60>, 'perms': {'change': True, 'add': True, 'delete': True}, 'admin_url': '/admin/auths/user/'}], 'app_label': 'auths', 'has_module_perms': True, 'name': 'Auths', 'app_url': '/admin/auths/'}, {'models': [{'add_url': '/admin/contenttypes/contenttype/add/', 'object_name': 'ContentType', 'name': <django.utils.functional.lazy.<locals>.__proxy__ object at 0x7fa5309da390>, 'perms': {'change': True, 'add': True, 'delete': True}, 'admin_url': '/admin/contenttypes/contenttype/'}], 'app_label': 'contenttypes', 'has_module_perms': True, 'name': <django.utils.functional.lazy.<locals>.__proxy__ object at 0x7fa53233b710>, 'app_url': '/admin/contenttypes/'}, {'models': [{'add_url': '/admin/oauth2_provider/accesstoken/add/', 'object_name': 'AccessToken', 'name': <django.utils.functional.lazy.<locals>.__proxy__ object at 0x7fa5302943c8>, 'perms': {'change': True, 'add': True, 'delete': True}, 'admin_url': '/admin/oauth2_provider/accesstoken/'}, {'add_url': '/admin/oauth2_provider/application/add/', 'object_name': 'Application', 'name': <django.utils.functional.lazy.<locals>.__proxy__ object at 0x7fa530294438>, 'perms': {'change': True, 'add': True, 'delete': True}, 'admin_url': '/admin/oauth2_provider/application/'}, {'add_url': '/admin/oauth2_provider/grant/add/', 'object_name': 'Grant', 'name': <django.utils.functional.lazy.<locals>.__proxy__ object at 0x7fa5309da710>, 'perms': {'change': True, 'add': True, 'delete': True}, 'admin_url': '/admin/oauth2_provider/grant/'}, {'add_url': '/admin/oauth2_provider/refreshtoken/add/', 'object_name': 'RefreshToken', 'name': <django.utils.functional.lazy.<locals>.__proxy__ object at 0x7fa530294c50>, 'perms': {'change': True, 'add': True, 'delete': True}, 'admin_url': '/admin/oauth2_provider/refreshtoken/'}], 'app_label': 'oauth2_provider', 'has_module_perms': True, 'name': 'Django OAuth Toolkit', 'app_url': '/admin/oauth2_provider/'}, {'models': [{'add_url': '/admin/dper/persona/add/', 'object_name': 'Persona', 'name': <django.utils.functional.lazy.<locals>.__proxy__ object at 0x7fa5302944a8>, 'perms': {'change': True, 'add': True, 'delete': True}, 'admin_url': '/admin/dper/persona/'}, {'add_url': '/admin/dper/profecion/add/', 'object_name': 'Profecion', 'name': <django.utils.functional.lazy.<locals>.__proxy__ object at 0x7fa53052d080>, 'perms': {'change': True, 'add': True, 'delete': True}, 'admin_url': '/admin/dper/profecion/'}], 'app_label': 'dper', 'has_module_perms': True, 'name': 'Dper', 'app_url': '/admin/dper/'}], 'app_list': [{'models': [{'add_url': '/admin/auth/group/add/', 'object_name': 'Group', 'name': <django.utils.functional.lazy.<locals>.__proxy__ object at 0x7fa53023cdd8>, 'perms': {'change': True, 'add': True, 'delete': True}, 'admin_url': '/admin/auth/group/'}, {'add_url': '/admin/auth/permission/add/', 'object_name': 'Permission', 'name': <django.utils.functional.lazy.<locals>.__proxy__ object at 0x7fa530288ef0>, 'perms': {'change': True, 'add': True, 'delete': True}, 'admin_url': '/admin/auth/permission/'}], 'app_label': 'auth', 'has_module_perms': True, 'name': <django.utils.functional.lazy.<locals>.__proxy__ object at 0x7fa532333f60>, 'app_url': '/admin/auth/'}, {'models': [{'add_url': '/admin/auths/hierarchytype/add/', 'object_name': 'HierarchyType', 'name': <django.utils.functional.lazy.<locals>.__proxy__ object at 0x7fa5302a2d68>, 'perms': {'change': True, 'add': True, 'delete': True}, 'admin_url': '/admin/auths/hierarchytype/'}, {'add_url': '/admin/auths/hierarchy/add/', 'object_name': 'Hierarchy', 'name': <django.utils.functional.lazy.<locals>.__proxy__ object at 0x7fa530288ac8>, 'perms': {'change': True, 'add': True, 'delete': True}, 'admin_url': '/admin/auths/hierarchy/'}, {'add_url': '/admin/auths/menu/add/', 'object_name': 'Menu', 'name': <django.utils.functional.lazy.<locals>.__proxy__ object at 0x7fa52b7c6c88>, 'perms': {'change': True, 'add': True, 'delete': True}, 'admin_url': '/admin/auths/menu/'}, {'add_url': '/admin/auths/person/add/', 'object_name': 'Person', 'name': <django.utils.functional.lazy.<locals>.__proxy__ object at 0x7fa5302a2748>, 'perms': {'change': True, 'add': True, 'delete': True}, 'admin_url': '/admin/auths/person/'}, {'add_url': '/admin/auths/userhierarchygroup/add/', 'object_name': 'UserHierarchyGroup', 'name': <django.utils.functional.lazy.<locals>.__proxy__ object at 0x7fa52b7c6d30>, 'perms': {'change': True, 'add': True, 'delete': True}, 'admin_url': '/admin/auths/userhierarchygroup/'}, {'add_url': '/admin/auths/userhierarchypermission/add/', 'object_name': 'UserHierarchyPermission', 'name': <django.utils.functional.lazy.<locals>.__proxy__ object at 0x7fa53023c940>, 'perms': {'change': True, 'add': True, 'delete': True}, 'admin_url': '/admin/auths/userhierarchypermission/'}, {'add_url': '/admin/auths/user/add/', 'object_name': 'User', 'name': <django.utils.functional.lazy.<locals>.__proxy__ object at 0x7fa53023c470>, 'perms': {'change': True, 'add': True, 'delete': True}, 'admin_url': '/admin/auths/user/'}], 'app_label': 'auths', 'has_module_perms': True, 'name': 'Auths', 'app_url': '/admin/auths/'}, {'models': [{'add_url': '/admin/contenttypes/contenttype/add/', 'object_name': 'ContentType', 'name': <django.utils.functional.lazy.<locals>.__proxy__ object at 0x7fa53023ccc0>, 'perms': {'change': True, 'add': True, 'delete': True}, 'admin_url': '/admin/contenttypes/contenttype/'}], 'app_label': 'contenttypes', 'has_module_perms': True, 'name': <django.utils.functional.lazy.<locals>.__proxy__ object at 0x7fa53233b710>, 'app_url': '/admin/contenttypes/'}, {'models': [{'add_url': '/admin/oauth2_provider/accesstoken/add/', 'object_name': 'AccessToken', 'name': <django.utils.functional.lazy.<locals>.__proxy__ object at 0x7fa5302a2cc0>, 'perms': {'change': True, 'add': True, 'delete': True}, 'admin_url': '/admin/oauth2_provider/accesstoken/'}, {'add_url': '/admin/oauth2_provider/application/add/', 'object_name': 'Application', 'name': <django.utils.functional.lazy.<locals>.__proxy__ object at 0x7fa530288f60>, 'perms': {'change': True, 'add': True, 'delete': True}, 'admin_url': '/admin/oauth2_provider/application/'}, {'add_url': '/admin/oauth2_provider/grant/add/', 'object_name': 'Grant', 'name': <django.utils.functional.lazy.<locals>.__proxy__ object at 0x7fa53023cf98>, 'perms': {'change': True, 'add': True, 'delete': True}, 'admin_url': '/admin/oauth2_provider/grant/'}, {'add_url': '/admin/oauth2_provider/refreshtoken/add/', 'object_name': 'RefreshToken', 'name': <django.utils.functional.lazy.<locals>.__proxy__ object at 0x7fa530288908>, 'perms': {'change': True, 'add': True, 'delete': True}, 'admin_url': '/admin/oauth2_provider/refreshtoken/'}], 'app_label': 'oauth2_provider', 'has_module_perms': True, 'name': 'Django OAuth Toolkit', 'app_url': '/admin/oauth2_provider/'}, {'models': [{'add_url': '/admin/dper/persona/add/', 'object_name': 'Persona', 'name': <django.utils.functional.lazy.<locals>.__proxy__ object at 0x7fa5302a27f0>, 'perms': {'change': True, 'add': True, 'delete': True}, 'admin_url': '/admin/dper/persona/'}, {'add_url': '/admin/dper/profecion/add/', 'object_name': 'Profecion', 'name': <django.utils.functional.lazy.<locals>.__proxy__ object at 0x7fa53023cac8>, 'perms': {'change': True, 'add': True, 'delete': True}, 'admin_url': '/admin/dper/profecion/'}], 'app_label': 'dper', 'has_module_perms': True, 'name': 'Dper', 'app_url': '/admin/dper/'}], 'LANGUAGE_BIDI': False, 'site_url': '/', 'site_header': <django.utils.functional.lazy.<locals>.__proxy__ object at 0x7fa532333438>, 'title': <django.utils.functional.lazy.<locals>.__proxy__ object at 0x7fa5323337f0>, 'has_permission': True, 'LANGUAGE_CODE': 'en-us'}]"
[2016-12-12 22:35:23] DEBUG [django.db.backends:89] (0.000) SELECT "django_admin_log"."id", "django_admin_log"."action_time", "django_admin_log"."user_id", "django_admin_log"."content_type_id", "django_admin_log"."object_id", "django_admin_log"."object_repr", "django_admin_log"."action_flag", "django_admin_log"."change_message", "auths_user"."password", "auths_user"."last_login", "auths_user"."is_superuser", "auths_user"."username", "auths_user"."first_name", "auths_user"."last_name", "auths_user"."email", "auths_user"."is_staff", "auths_user"."is_active", "auths_user"."date_joined", "auths_user"."id", "auths_user"."last_hierarchy_id", "auths_user"."last_module_id", "auths_user"."person_id", "auths_user"."updated_at", "auths_user"."registered_by", "django_content_type"."id", "django_content_type"."app_label", "django_content_type"."model" FROM "django_admin_log" INNER JOIN "auths_user" ON ("django_admin_log"."user_id" = "auths_user"."id") LEFT OUTER JOIN "django_content_type" ON ("django_admin_log"."content_type_id" = "django_content_type"."id") WHERE "django_admin_log"."user_id" = '2f22885837cb451cb36a4ff40a7a35dc' ORDER BY "django_admin_log"."action_time" DESC LIMIT 10; args=('2f22885837cb451cb36a4ff40a7a35dc',)
