[2016-11-19 23:21:47] DEBUG [django.db.backends:89] (0.126) 
            SELECT name, type FROM sqlite_master
            WHERE type in ('table', 'view') AND NOT name='sqlite_sequence'
            ORDER BY name; args=None
[2016-11-19 23:21:47] DEBUG [django.db.backends:89] (0.000) SELECT "django_migrations"."app", "django_migrations"."name" FROM "django_migrations"; args=()
[2016-11-19 23:21:55] DEBUG [django.db.backends:89] (0.002) SELECT "django_session"."session_key", "django_session"."session_data", "django_session"."expire_date" FROM "django_session" WHERE ("django_session"."expire_date" > '2016-11-19 23:21:55.429716' AND "django_session"."session_key" = 'kgemnjvasp2jaiw4oqli8d5va4lo3twk'); args=('2016-11-19 23:21:55.429716', 'kgemnjvasp2jaiw4oqli8d5va4lo3twk')
[2016-11-19 23:21:55] DEBUG [django.db.backends:89] (0.001) SELECT "auths_user"."password", "auths_user"."last_login", "auths_user"."is_superuser", "auths_user"."username", "auths_user"."first_name", "auths_user"."last_name", "auths_user"."email", "auths_user"."is_staff", "auths_user"."is_active", "auths_user"."date_joined", "auths_user"."id", "auths_user"."last_hierarchy_id", "auths_user"."last_module_id", "auths_user"."person_id", "auths_user"."updated_at", "auths_user"."registered_by" FROM "auths_user" WHERE "auths_user"."id" = '3d175268c0c44515b5572bd73229dc1b'; args=('3d175268c0c44515b5572bd73229dc1b',)
[2016-11-19 23:21:55] DEBUG [django.template:927] Exception while resolving variable 'is_popup' in template 'admin/index.html'.
Traceback (most recent call last):
  File "/home/roger/.virtualenvs/learning/lib/python3.5/site-packages/django/template/base.py", line 883, in _resolve_lookup
    current = current[bit]
  File "/home/roger/.virtualenvs/learning/lib/python3.5/site-packages/django/template/context.py", line 77, in __getitem__
    raise KeyError(key)
KeyError: 'is_popup'

During handling of the above exception, another exception occurred:

Traceback (most recent call last):
  File "/home/roger/.virtualenvs/learning/lib/python3.5/site-packages/django/template/base.py", line 889, in _resolve_lookup
    if isinstance(current, BaseContext) and getattr(type(current), bit):
AttributeError: type object 'RequestContext' has no attribute 'is_popup'

During handling of the above exception, another exception occurred:

Traceback (most recent call last):
  File "/home/roger/.virtualenvs/learning/lib/python3.5/site-packages/django/template/base.py", line 898, in _resolve_lookup
    current = current[int(bit)]
ValueError: invalid literal for int() with base 10: 'is_popup'

During handling of the above exception, another exception occurred:

Traceback (most recent call last):
  File "/home/roger/.virtualenvs/learning/lib/python3.5/site-packages/django/template/base.py", line 905, in _resolve_lookup
    (bit, current))  # missing attribute
django.template.base.VariableDoesNotExist: Failed lookup for key [is_popup] in "[{'True': True, 'None': None, 'False': False}, {'messages': <django.contrib.messages.storage.fallback.FallbackStorage object at 0x7f0fe127b898>, 'perms': <django.contrib.auth.context_processors.PermWrapper object at 0x7f0fda673a90>, 'csrf_token': <SimpleLazyObject: <function csrf.<locals>._get_val at 0x7f0fdb95b730>>, 'DEFAULT_MESSAGE_LEVELS': {'SUCCESS': 25, 'DEBUG': 10, 'INFO': 20, 'ERROR': 40, 'WARNING': 30}, 'request': <WSGIRequest: GET '/admin/'>, 'user': <SimpleLazyObject: <User: roger>>}, {}, {'LANGUAGE_CODE': 'en-us', 'has_permission': True, 'site_header': <django.utils.functional.lazy.<locals>.__proxy__ object at 0x7f0fe1a2f470>, 'site_title': <django.utils.functional.lazy.<locals>.__proxy__ object at 0x7f0fe1a93588>, 'app_list': [{'app_url': '/admin/auth/', 'name': <django.utils.functional.lazy.<locals>.__proxy__ object at 0x7f0fe1a2ff98>, 'has_module_perms': True, 'app_label': 'auth', 'models': [{'admin_url': '/admin/auth/group/', 'name': <django.utils.functional.lazy.<locals>.__proxy__ object at 0x7f0fda6d1128>, 'add_url': '/admin/auth/group/add/', 'perms': {'change': True, 'delete': True, 'add': True}, 'object_name': 'Group'}, {'admin_url': '/admin/auth/permission/', 'name': <django.utils.functional.lazy.<locals>.__proxy__ object at 0x7f0fda6d9da0>, 'add_url': '/admin/auth/permission/add/', 'perms': {'change': True, 'delete': True, 'add': True}, 'object_name': 'Permission'}]}, {'app_url': '/admin/auths/', 'name': 'Auths', 'has_module_perms': True, 'app_label': 'auths', 'models': [{'admin_url': '/admin/auths/hierarchytype/', 'name': <django.utils.functional.lazy.<locals>.__proxy__ object at 0x7f0fda6d1048>, 'add_url': '/admin/auths/hierarchytype/add/', 'perms': {'change': True, 'delete': True, 'add': True}, 'object_name': 'HierarchyType'}, {'admin_url': '/admin/auths/hierarchy/', 'name': <django.utils.functional.lazy.<locals>.__proxy__ object at 0x7f0fda6d1240>, 'add_url': '/admin/auths/hierarchy/add/', 'perms': {'change': True, 'delete': True, 'add': True}, 'object_name': 'Hierarchy'}, {'admin_url': '/admin/auths/menu/', 'name': <django.utils.functional.lazy.<locals>.__proxy__ object at 0x7f0fda6d12b0>, 'add_url': '/admin/auths/menu/add/', 'perms': {'change': True, 'delete': True, 'add': True}, 'object_name': 'Menu'}, {'admin_url': '/admin/auths/person/', 'name': <django.utils.functional.lazy.<locals>.__proxy__ object at 0x7f0fda6f7e80>, 'add_url': '/admin/auths/person/add/', 'perms': {'change': True, 'delete': True, 'add': True}, 'object_name': 'Person'}, {'admin_url': '/admin/auths/userhierarchygroup/', 'name': <django.utils.functional.lazy.<locals>.__proxy__ object at 0x7f0fda6bbf98>, 'add_url': '/admin/auths/userhierarchygroup/add/', 'perms': {'change': True, 'delete': True, 'add': True}, 'object_name': 'UserHierarchyGroup'}, {'admin_url': '/admin/auths/userhierarchypermission/', 'name': <django.utils.functional.lazy.<locals>.__proxy__ object at 0x7f0fda6d1080>, 'add_url': '/admin/auths/userhierarchypermission/add/', 'perms': {'change': True, 'delete': True, 'add': True}, 'object_name': 'UserHierarchyPermission'}, {'admin_url': '/admin/auths/user/', 'name': <django.utils.functional.lazy.<locals>.__proxy__ object at 0x7f0fda6bb470>, 'add_url': '/admin/auths/user/add/', 'perms': {'change': True, 'delete': True, 'add': True}, 'object_name': 'User'}]}, {'app_url': '/admin/contenttypes/', 'name': <django.utils.functional.lazy.<locals>.__proxy__ object at 0x7f0fe1a37748>, 'has_module_perms': True, 'app_label': 'contenttypes', 'models': [{'admin_url': '/admin/contenttypes/contenttype/', 'name': <django.utils.functional.lazy.<locals>.__proxy__ object at 0x7f0fda6d10f0>, 'add_url': '/admin/contenttypes/contenttype/add/', 'perms': {'change': True, 'delete': True, 'add': True}, 'object_name': 'ContentType'}]}, {'app_url': '/admin/oauth2_provider/', 'name': 'Django OAuth Toolkit', 'has_module_perms': True, 'app_label': 'oauth2_provider', 'models': [{'admin_url': '/admin/oauth2_provider/accesstoken/', 'name': <django.utils.functional.lazy.<locals>.__proxy__ object at 0x7f0fda6d9dd8>, 'add_url': '/admin/oauth2_provider/accesstoken/add/', 'perms': {'change': True, 'delete': True, 'add': True}, 'object_name': 'AccessToken'}, {'admin_url': '/admin/oauth2_provider/application/', 'name': <django.utils.functional.lazy.<locals>.__proxy__ object at 0x7f0fda6bbfd0>, 'add_url': '/admin/oauth2_provider/application/add/', 'perms': {'change': True, 'delete': True, 'add': True}, 'object_name': 'Application'}, {'admin_url': '/admin/oauth2_provider/grant/', 'name': <django.utils.functional.lazy.<locals>.__proxy__ object at 0x7f0fda6d11d0>, 'add_url': '/admin/oauth2_provider/grant/add/', 'perms': {'change': True, 'delete': True, 'add': True}, 'object_name': 'Grant'}, {'admin_url': '/admin/oauth2_provider/refreshtoken/', 'name': <django.utils.functional.lazy.<locals>.__proxy__ object at 0x7f0fda6f7dd8>, 'add_url': '/admin/oauth2_provider/refreshtoken/add/', 'perms': {'change': True, 'delete': True, 'add': True}, 'object_name': 'RefreshToken'}]}, {'app_url': '/admin/dper/', 'name': 'Dper', 'has_module_perms': True, 'app_label': 'dper', 'models': [{'admin_url': '/admin/dper/persona/', 'name': <django.utils.functional.lazy.<locals>.__proxy__ object at 0x7f0fda6d1390>, 'add_url': '/admin/dper/persona/add/', 'perms': {'change': True, 'delete': True, 'add': True}, 'object_name': 'Persona'}, {'admin_url': '/admin/dper/profecion/', 'name': <django.utils.functional.lazy.<locals>.__proxy__ object at 0x7f0fda6d10b8>, 'add_url': '/admin/dper/profecion/add/', 'perms': {'change': True, 'delete': True, 'add': True}, 'object_name': 'Profecion'}]}], 'available_apps': [{'app_url': '/admin/auth/', 'name': <django.utils.functional.lazy.<locals>.__proxy__ object at 0x7f0fe1a2ff98>, 'has_module_perms': True, 'app_label': 'auth', 'models': [{'admin_url': '/admin/auth/group/', 'name': <django.utils.functional.lazy.<locals>.__proxy__ object at 0x7f0fda6d17b8>, 'add_url': '/admin/auth/group/add/', 'perms': {'change': True, 'delete': True, 'add': True}, 'object_name': 'Group'}, {'admin_url': '/admin/auth/permission/', 'name': <django.utils.functional.lazy.<locals>.__proxy__ object at 0x7f0fda6d1470>, 'add_url': '/admin/auth/permission/add/', 'perms': {'change': True, 'delete': True, 'add': True}, 'object_name': 'Permission'}]}, {'app_url': '/admin/auths/', 'name': 'Auths', 'has_module_perms': True, 'app_label': 'auths', 'models': [{'admin_url': '/admin/auths/hierarchytype/', 'name': <django.utils.functional.lazy.<locals>.__proxy__ object at 0x7f0fda6d1748>, 'add_url': '/admin/auths/hierarchytype/add/', 'perms': {'change': True, 'delete': True, 'add': True}, 'object_name': 'HierarchyType'}, {'admin_url': '/admin/auths/hierarchy/', 'name': <django.utils.functional.lazy.<locals>.__proxy__ object at 0x7f0fda6d1908>, 'add_url': '/admin/auths/hierarchy/add/', 'perms': {'change': True, 'delete': True, 'add': True}, 'object_name': 'Hierarchy'}, {'admin_url': '/admin/auths/menu/', 'name': <django.utils.functional.lazy.<locals>.__proxy__ object at 0x7f0fda6d1978>, 'add_url': '/admin/auths/menu/add/', 'perms': {'change': True, 'delete': True, 'add': True}, 'object_name': 'Menu'}, {'admin_url': '/admin/auths/person/', 'name': <django.utils.functional.lazy.<locals>.__proxy__ object at 0x7f0fda6d1630>, 'add_url': '/admin/auths/person/add/', 'perms': {'change': True, 'delete': True, 'add': True}, 'object_name': 'Person'}, {'admin_url': '/admin/auths/userhierarchygroup/', 'name': <django.utils.functional.lazy.<locals>.__proxy__ object at 0x7f0fda6d15f8>, 'add_url': '/admin/auths/userhierarchygroup/add/', 'perms': {'change': True, 'delete': True, 'add': True}, 'object_name': 'UserHierarchyGroup'}, {'admin_url': '/admin/auths/userhierarchypermission/', 'name': <django.utils.functional.lazy.<locals>.__proxy__ object at 0x7f0fda6d1710>, 'add_url': '/admin/auths/userhierarchypermission/add/', 'perms': {'change': True, 'delete': True, 'add': True}, 'object_name': 'UserHierarchyPermission'}, {'admin_url': '/admin/auths/user/', 'name': <django.utils.functional.lazy.<locals>.__proxy__ object at 0x7f0fda6d16a0>, 'add_url': '/admin/auths/user/add/', 'perms': {'change': True, 'delete': True, 'add': True}, 'object_name': 'User'}]}, {'app_url': '/admin/contenttypes/', 'name': <django.utils.functional.lazy.<locals>.__proxy__ object at 0x7f0fe1a37748>, 'has_module_perms': True, 'app_label': 'contenttypes', 'models': [{'admin_url': '/admin/contenttypes/contenttype/', 'name': <django.utils.functional.lazy.<locals>.__proxy__ object at 0x7f0fda6d1828>, 'add_url': '/admin/contenttypes/contenttype/add/', 'perms': {'change': True, 'delete': True, 'add': True}, 'object_name': 'ContentType'}]}, {'app_url': '/admin/oauth2_provider/', 'name': 'Django OAuth Toolkit', 'has_module_perms': True, 'app_label': 'oauth2_provider', 'models': [{'admin_url': '/admin/oauth2_provider/accesstoken/', 'name': <django.utils.functional.lazy.<locals>.__proxy__ object at 0x7f0fda6d1668>, 'add_url': '/admin/oauth2_provider/accesstoken/add/', 'perms': {'change': True, 'delete': True, 'add': True}, 'object_name': 'AccessToken'}, {'admin_url': '/admin/oauth2_provider/application/', 'name': <django.utils.functional.lazy.<locals>.__proxy__ object at 0x7f0fda6d16d8>, 'add_url': '/admin/oauth2_provider/application/add/', 'perms': {'change': True, 'delete': True, 'add': True}, 'object_name': 'Application'}, {'admin_url': '/admin/oauth2_provider/grant/', 'name': <django.utils.functional.lazy.<locals>.__proxy__ object at 0x7f0fda6d1898>, 'add_url': '/admin/oauth2_provider/grant/add/', 'perms': {'change': True, 'delete': True, 'add': True}, 'object_name': 'Grant'}, {'admin_url': '/admin/oauth2_provider/refreshtoken/', 'name': <django.utils.functional.lazy.<locals>.__proxy__ object at 0x7f0fda6d15c0>, 'add_url': '/admin/oauth2_provider/refreshtoken/add/', 'perms': {'change': True, 'delete': True, 'add': True}, 'object_name': 'RefreshToken'}]}, {'app_url': '/admin/dper/', 'name': 'Dper', 'has_module_perms': True, 'app_label': 'dper', 'models': [{'admin_url': '/admin/dper/persona/', 'name': <django.utils.functional.lazy.<locals>.__proxy__ object at 0x7f0fdbbf1f28>, 'add_url': '/admin/dper/persona/add/', 'perms': {'change': True, 'delete': True, 'add': True}, 'object_name': 'Persona'}, {'admin_url': '/admin/dper/profecion/', 'name': <django.utils.functional.lazy.<locals>.__proxy__ object at 0x7f0fda6d1780>, 'add_url': '/admin/dper/profecion/add/', 'perms': {'change': True, 'delete': True, 'add': True}, 'object_name': 'Profecion'}]}], 'title': <django.utils.functional.lazy.<locals>.__proxy__ object at 0x7f0fe1a2f828>, 'site_url': '/', 'LANGUAGE_BIDI': False}]"
[2016-11-19 23:21:55] DEBUG [django.template:927] Exception while resolving variable 'is_popup' in template 'admin/index.html'.
Traceback (most recent call last):
  File "/home/roger/.virtualenvs/learning/lib/python3.5/site-packages/django/template/base.py", line 883, in _resolve_lookup
    current = current[bit]
  File "/home/roger/.virtualenvs/learning/lib/python3.5/site-packages/django/template/context.py", line 77, in __getitem__
    raise KeyError(key)
KeyError: 'is_popup'

During handling of the above exception, another exception occurred:

Traceback (most recent call last):
  File "/home/roger/.virtualenvs/learning/lib/python3.5/site-packages/django/template/base.py", line 889, in _resolve_lookup
    if isinstance(current, BaseContext) and getattr(type(current), bit):
AttributeError: type object 'RequestContext' has no attribute 'is_popup'

During handling of the above exception, another exception occurred:

Traceback (most recent call last):
  File "/home/roger/.virtualenvs/learning/lib/python3.5/site-packages/django/template/base.py", line 898, in _resolve_lookup
    current = current[int(bit)]
ValueError: invalid literal for int() with base 10: 'is_popup'

During handling of the above exception, another exception occurred:

Traceback (most recent call last):
  File "/home/roger/.virtualenvs/learning/lib/python3.5/site-packages/django/template/base.py", line 905, in _resolve_lookup
    (bit, current))  # missing attribute
django.template.base.VariableDoesNotExist: Failed lookup for key [is_popup] in "[{'True': True, 'None': None, 'False': False}, {'messages': <django.contrib.messages.storage.fallback.FallbackStorage object at 0x7f0fe127b898>, 'perms': <django.contrib.auth.context_processors.PermWrapper object at 0x7f0fda673a90>, 'csrf_token': <SimpleLazyObject: <function csrf.<locals>._get_val at 0x7f0fdb95b730>>, 'DEFAULT_MESSAGE_LEVELS': {'SUCCESS': 25, 'DEBUG': 10, 'INFO': 20, 'ERROR': 40, 'WARNING': 30}, 'request': <WSGIRequest: GET '/admin/'>, 'user': <SimpleLazyObject: <User: roger>>}, {}, {'LANGUAGE_CODE': 'en-us', 'has_permission': True, 'site_header': <django.utils.functional.lazy.<locals>.__proxy__ object at 0x7f0fe1a2f470>, 'site_title': <django.utils.functional.lazy.<locals>.__proxy__ object at 0x7f0fe1a93588>, 'app_list': [{'app_url': '/admin/auth/', 'name': <django.utils.functional.lazy.<locals>.__proxy__ object at 0x7f0fe1a2ff98>, 'has_module_perms': True, 'app_label': 'auth', 'models': [{'admin_url': '/admin/auth/group/', 'name': <django.utils.functional.lazy.<locals>.__proxy__ object at 0x7f0fda6d1128>, 'add_url': '/admin/auth/group/add/', 'perms': {'change': True, 'delete': True, 'add': True}, 'object_name': 'Group'}, {'admin_url': '/admin/auth/permission/', 'name': <django.utils.functional.lazy.<locals>.__proxy__ object at 0x7f0fda6d9da0>, 'add_url': '/admin/auth/permission/add/', 'perms': {'change': True, 'delete': True, 'add': True}, 'object_name': 'Permission'}]}, {'app_url': '/admin/auths/', 'name': 'Auths', 'has_module_perms': True, 'app_label': 'auths', 'models': [{'admin_url': '/admin/auths/hierarchytype/', 'name': <django.utils.functional.lazy.<locals>.__proxy__ object at 0x7f0fda6d1048>, 'add_url': '/admin/auths/hierarchytype/add/', 'perms': {'change': True, 'delete': True, 'add': True}, 'object_name': 'HierarchyType'}, {'admin_url': '/admin/auths/hierarchy/', 'name': <django.utils.functional.lazy.<locals>.__proxy__ object at 0x7f0fda6d1240>, 'add_url': '/admin/auths/hierarchy/add/', 'perms': {'change': True, 'delete': True, 'add': True}, 'object_name': 'Hierarchy'}, {'admin_url': '/admin/auths/menu/', 'name': <django.utils.functional.lazy.<locals>.__proxy__ object at 0x7f0fda6d12b0>, 'add_url': '/admin/auths/menu/add/', 'perms': {'change': True, 'delete': True, 'add': True}, 'object_name': 'Menu'}, {'admin_url': '/admin/auths/person/', 'name': <django.utils.functional.lazy.<locals>.__proxy__ object at 0x7f0fda6f7e80>, 'add_url': '/admin/auths/person/add/', 'perms': {'change': True, 'delete': True, 'add': True}, 'object_name': 'Person'}, {'admin_url': '/admin/auths/userhierarchygroup/', 'name': <django.utils.functional.lazy.<locals>.__proxy__ object at 0x7f0fda6bbf98>, 'add_url': '/admin/auths/userhierarchygroup/add/', 'perms': {'change': True, 'delete': True, 'add': True}, 'object_name': 'UserHierarchyGroup'}, {'admin_url': '/admin/auths/userhierarchypermission/', 'name': <django.utils.functional.lazy.<locals>.__proxy__ object at 0x7f0fda6d1080>, 'add_url': '/admin/auths/userhierarchypermission/add/', 'perms': {'change': True, 'delete': True, 'add': True}, 'object_name': 'UserHierarchyPermission'}, {'admin_url': '/admin/auths/user/', 'name': <django.utils.functional.lazy.<locals>.__proxy__ object at 0x7f0fda6bb470>, 'add_url': '/admin/auths/user/add/', 'perms': {'change': True, 'delete': True, 'add': True}, 'object_name': 'User'}]}, {'app_url': '/admin/contenttypes/', 'name': <django.utils.functional.lazy.<locals>.__proxy__ object at 0x7f0fe1a37748>, 'has_module_perms': True, 'app_label': 'contenttypes', 'models': [{'admin_url': '/admin/contenttypes/contenttype/', 'name': <django.utils.functional.lazy.<locals>.__proxy__ object at 0x7f0fda6d10f0>, 'add_url': '/admin/contenttypes/contenttype/add/', 'perms': {'change': True, 'delete': True, 'add': True}, 'object_name': 'ContentType'}]}, {'app_url': '/admin/oauth2_provider/', 'name': 'Django OAuth Toolkit', 'has_module_perms': True, 'app_label': 'oauth2_provider', 'models': [{'admin_url': '/admin/oauth2_provider/accesstoken/', 'name': <django.utils.functional.lazy.<locals>.__proxy__ object at 0x7f0fda6d9dd8>, 'add_url': '/admin/oauth2_provider/accesstoken/add/', 'perms': {'change': True, 'delete': True, 'add': True}, 'object_name': 'AccessToken'}, {'admin_url': '/admin/oauth2_provider/application/', 'name': <django.utils.functional.lazy.<locals>.__proxy__ object at 0x7f0fda6bbfd0>, 'add_url': '/admin/oauth2_provider/application/add/', 'perms': {'change': True, 'delete': True, 'add': True}, 'object_name': 'Application'}, {'admin_url': '/admin/oauth2_provider/grant/', 'name': <django.utils.functional.lazy.<locals>.__proxy__ object at 0x7f0fda6d11d0>, 'add_url': '/admin/oauth2_provider/grant/add/', 'perms': {'change': True, 'delete': True, 'add': True}, 'object_name': 'Grant'}, {'admin_url': '/admin/oauth2_provider/refreshtoken/', 'name': <django.utils.functional.lazy.<locals>.__proxy__ object at 0x7f0fda6f7dd8>, 'add_url': '/admin/oauth2_provider/refreshtoken/add/', 'perms': {'change': True, 'delete': True, 'add': True}, 'object_name': 'RefreshToken'}]}, {'app_url': '/admin/dper/', 'name': 'Dper', 'has_module_perms': True, 'app_label': 'dper', 'models': [{'admin_url': '/admin/dper/persona/', 'name': <django.utils.functional.lazy.<locals>.__proxy__ object at 0x7f0fda6d1390>, 'add_url': '/admin/dper/persona/add/', 'perms': {'change': True, 'delete': True, 'add': True}, 'object_name': 'Persona'}, {'admin_url': '/admin/dper/profecion/', 'name': <django.utils.functional.lazy.<locals>.__proxy__ object at 0x7f0fda6d10b8>, 'add_url': '/admin/dper/profecion/add/', 'perms': {'change': True, 'delete': True, 'add': True}, 'object_name': 'Profecion'}]}], 'available_apps': [{'app_url': '/admin/auth/', 'name': <django.utils.functional.lazy.<locals>.__proxy__ object at 0x7f0fe1a2ff98>, 'has_module_perms': True, 'app_label': 'auth', 'models': [{'admin_url': '/admin/auth/group/', 'name': <django.utils.functional.lazy.<locals>.__proxy__ object at 0x7f0fda6d17b8>, 'add_url': '/admin/auth/group/add/', 'perms': {'change': True, 'delete': True, 'add': True}, 'object_name': 'Group'}, {'admin_url': '/admin/auth/permission/', 'name': <django.utils.functional.lazy.<locals>.__proxy__ object at 0x7f0fda6d1470>, 'add_url': '/admin/auth/permission/add/', 'perms': {'change': True, 'delete': True, 'add': True}, 'object_name': 'Permission'}]}, {'app_url': '/admin/auths/', 'name': 'Auths', 'has_module_perms': True, 'app_label': 'auths', 'models': [{'admin_url': '/admin/auths/hierarchytype/', 'name': <django.utils.functional.lazy.<locals>.__proxy__ object at 0x7f0fda6d1748>, 'add_url': '/admin/auths/hierarchytype/add/', 'perms': {'change': True, 'delete': True, 'add': True}, 'object_name': 'HierarchyType'}, {'admin_url': '/admin/auths/hierarchy/', 'name': <django.utils.functional.lazy.<locals>.__proxy__ object at 0x7f0fda6d1908>, 'add_url': '/admin/auths/hierarchy/add/', 'perms': {'change': True, 'delete': True, 'add': True}, 'object_name': 'Hierarchy'}, {'admin_url': '/admin/auths/menu/', 'name': <django.utils.functional.lazy.<locals>.__proxy__ object at 0x7f0fda6d1978>, 'add_url': '/admin/auths/menu/add/', 'perms': {'change': True, 'delete': True, 'add': True}, 'object_name': 'Menu'}, {'admin_url': '/admin/auths/person/', 'name': <django.utils.functional.lazy.<locals>.__proxy__ object at 0x7f0fda6d1630>, 'add_url': '/admin/auths/person/add/', 'perms': {'change': True, 'delete': True, 'add': True}, 'object_name': 'Person'}, {'admin_url': '/admin/auths/userhierarchygroup/', 'name': <django.utils.functional.lazy.<locals>.__proxy__ object at 0x7f0fda6d15f8>, 'add_url': '/admin/auths/userhierarchygroup/add/', 'perms': {'change': True, 'delete': True, 'add': True}, 'object_name': 'UserHierarchyGroup'}, {'admin_url': '/admin/auths/userhierarchypermission/', 'name': <django.utils.functional.lazy.<locals>.__proxy__ object at 0x7f0fda6d1710>, 'add_url': '/admin/auths/userhierarchypermission/add/', 'perms': {'change': True, 'delete': True, 'add': True}, 'object_name': 'UserHierarchyPermission'}, {'admin_url': '/admin/auths/user/', 'name': <django.utils.functional.lazy.<locals>.__proxy__ object at 0x7f0fda6d16a0>, 'add_url': '/admin/auths/user/add/', 'perms': {'change': True, 'delete': True, 'add': True}, 'object_name': 'User'}]}, {'app_url': '/admin/contenttypes/', 'name': <django.utils.functional.lazy.<locals>.__proxy__ object at 0x7f0fe1a37748>, 'has_module_perms': True, 'app_label': 'contenttypes', 'models': [{'admin_url': '/admin/contenttypes/contenttype/', 'name': <django.utils.functional.lazy.<locals>.__proxy__ object at 0x7f0fda6d1828>, 'add_url': '/admin/contenttypes/contenttype/add/', 'perms': {'change': True, 'delete': True, 'add': True}, 'object_name': 'ContentType'}]}, {'app_url': '/admin/oauth2_provider/', 'name': 'Django OAuth Toolkit', 'has_module_perms': True, 'app_label': 'oauth2_provider', 'models': [{'admin_url': '/admin/oauth2_provider/accesstoken/', 'name': <django.utils.functional.lazy.<locals>.__proxy__ object at 0x7f0fda6d1668>, 'add_url': '/admin/oauth2_provider/accesstoken/add/', 'perms': {'change': True, 'delete': True, 'add': True}, 'object_name': 'AccessToken'}, {'admin_url': '/admin/oauth2_provider/application/', 'name': <django.utils.functional.lazy.<locals>.__proxy__ object at 0x7f0fda6d16d8>, 'add_url': '/admin/oauth2_provider/application/add/', 'perms': {'change': True, 'delete': True, 'add': True}, 'object_name': 'Application'}, {'admin_url': '/admin/oauth2_provider/grant/', 'name': <django.utils.functional.lazy.<locals>.__proxy__ object at 0x7f0fda6d1898>, 'add_url': '/admin/oauth2_provider/grant/add/', 'perms': {'change': True, 'delete': True, 'add': True}, 'object_name': 'Grant'}, {'admin_url': '/admin/oauth2_provider/refreshtoken/', 'name': <django.utils.functional.lazy.<locals>.__proxy__ object at 0x7f0fda6d15c0>, 'add_url': '/admin/oauth2_provider/refreshtoken/add/', 'perms': {'change': True, 'delete': True, 'add': True}, 'object_name': 'RefreshToken'}]}, {'app_url': '/admin/dper/', 'name': 'Dper', 'has_module_perms': True, 'app_label': 'dper', 'models': [{'admin_url': '/admin/dper/persona/', 'name': <django.utils.functional.lazy.<locals>.__proxy__ object at 0x7f0fdbbf1f28>, 'add_url': '/admin/dper/persona/add/', 'perms': {'change': True, 'delete': True, 'add': True}, 'object_name': 'Persona'}, {'admin_url': '/admin/dper/profecion/', 'name': <django.utils.functional.lazy.<locals>.__proxy__ object at 0x7f0fda6d1780>, 'add_url': '/admin/dper/profecion/add/', 'perms': {'change': True, 'delete': True, 'add': True}, 'object_name': 'Profecion'}]}], 'title': <django.utils.functional.lazy.<locals>.__proxy__ object at 0x7f0fe1a2f828>, 'site_url': '/', 'LANGUAGE_BIDI': False}]"
[2016-11-19 23:21:55] DEBUG [django.db.backends:89] (0.001) SELECT "django_admin_log"."id", "django_admin_log"."action_time", "django_admin_log"."user_id", "django_admin_log"."content_type_id", "django_admin_log"."object_id", "django_admin_log"."object_repr", "django_admin_log"."action_flag", "django_admin_log"."change_message", "auths_user"."password", "auths_user"."last_login", "auths_user"."is_superuser", "auths_user"."username", "auths_user"."first_name", "auths_user"."last_name", "auths_user"."email", "auths_user"."is_staff", "auths_user"."is_active", "auths_user"."date_joined", "auths_user"."id", "auths_user"."last_hierarchy_id", "auths_user"."last_module_id", "auths_user"."person_id", "auths_user"."updated_at", "auths_user"."registered_by", "django_content_type"."id", "django_content_type"."app_label", "django_content_type"."model" FROM "django_admin_log" INNER JOIN "auths_user" ON ("django_admin_log"."user_id" = "auths_user"."id") LEFT OUTER JOIN "django_content_type" ON ("django_admin_log"."content_type_id" = "django_content_type"."id") WHERE "django_admin_log"."user_id" = '3d175268c0c44515b5572bd73229dc1b' ORDER BY "django_admin_log"."action_time" DESC LIMIT 10; args=('3d175268c0c44515b5572bd73229dc1b',)
[2016-11-19 23:21:56] WARNING [django.request:182] Not Found: /favicon.ico
[2016-11-19 23:21:56] DEBUG [django.template:927] Exception while resolving variable 'name' in template 'unknown'.
Traceback (most recent call last):
  File "/home/roger/.virtualenvs/learning/lib/python3.5/site-packages/django/core/handlers/base.py", line 134, in get_response
    resolver_match = resolver.resolve(request.path_info)
  File "/home/roger/.virtualenvs/learning/lib/python3.5/site-packages/django/core/urlresolvers.py", line 404, in resolve
    raise Resolver404({'tried': tried, 'path': new_path})
django.core.urlresolvers.Resolver404: {'tried': [[<RegexURLResolver <RegexURLPattern list> (admin:admin) ^admin/>], [<RegexURLResolver <module 'django.contrib.admindocs.urls' from '/home/roger/.virtualenvs/learning/lib/python3.5/site-packages/django/contrib/admindocs/urls.py'> (None:None) ^admin/doc/>], [<RegexURLResolver <module 'rest_framework.urls' from '/home/roger/.virtualenvs/learning/lib/python3.5/site-packages/rest_framework/urls.py'> (rest_framework:rest_framework) ^api-auth/>], [<RegexURLResolver <module 'oauth2_provider.urls' from '/home/roger/.virtualenvs/learning/lib/python3.5/site-packages/oauth2_provider/urls.py'> (None:oauth2_provider) ^o/>], [<RegexURLResolver <module 'ioteca_service_apps.auths_api.urls' from '/home/roger/proyectos/learning/learning/ioteca_service/ioteca_service_apps/auths_api/urls.py'> (None:None) ^api/auths/>], [<RegexURLResolver <module 'ioteca_service_apps.dper.urls' from '/home/roger/proyectos/learning/learning/ioteca_service/ioteca_service_apps/dper/urls.py'> (None:None) ^api/dper/>]], 'path': 'favicon.ico'}

During handling of the above exception, another exception occurred:

Traceback (most recent call last):
  File "/home/roger/.virtualenvs/learning/lib/python3.5/site-packages/django/template/base.py", line 883, in _resolve_lookup
    current = current[bit]
TypeError: 'RegexURLResolver' object is not subscriptable

During handling of the above exception, another exception occurred:

Traceback (most recent call last):
  File "/home/roger/.virtualenvs/learning/lib/python3.5/site-packages/django/template/base.py", line 891, in _resolve_lookup
    current = getattr(current, bit)
AttributeError: 'RegexURLResolver' object has no attribute 'name'

During handling of the above exception, another exception occurred:

Traceback (most recent call last):
  File "/home/roger/.virtualenvs/learning/lib/python3.5/site-packages/django/template/base.py", line 898, in _resolve_lookup
    current = current[int(bit)]
ValueError: invalid literal for int() with base 10: 'name'

During handling of the above exception, another exception occurred:

Traceback (most recent call last):
  File "/home/roger/.virtualenvs/learning/lib/python3.5/site-packages/django/template/base.py", line 905, in _resolve_lookup
    (bit, current))  # missing attribute
django.template.base.VariableDoesNotExist: Failed lookup for key [name] in '<RegexURLResolver <RegexURLPattern list> (admin:admin) ^admin/>'
[2016-11-19 23:21:56] DEBUG [django.template:927] Exception while resolving variable 'name' in template 'unknown'.
Traceback (most recent call last):
  File "/home/roger/.virtualenvs/learning/lib/python3.5/site-packages/django/core/handlers/base.py", line 134, in get_response
    resolver_match = resolver.resolve(request.path_info)
  File "/home/roger/.virtualenvs/learning/lib/python3.5/site-packages/django/core/urlresolvers.py", line 404, in resolve
    raise Resolver404({'tried': tried, 'path': new_path})
django.core.urlresolvers.Resolver404: {'tried': [[<RegexURLResolver <RegexURLPattern list> (admin:admin) ^admin/>], [<RegexURLResolver <module 'django.contrib.admindocs.urls' from '/home/roger/.virtualenvs/learning/lib/python3.5/site-packages/django/contrib/admindocs/urls.py'> (None:None) ^admin/doc/>], [<RegexURLResolver <module 'rest_framework.urls' from '/home/roger/.virtualenvs/learning/lib/python3.5/site-packages/rest_framework/urls.py'> (rest_framework:rest_framework) ^api-auth/>], [<RegexURLResolver <module 'oauth2_provider.urls' from '/home/roger/.virtualenvs/learning/lib/python3.5/site-packages/oauth2_provider/urls.py'> (None:oauth2_provider) ^o/>], [<RegexURLResolver <module 'ioteca_service_apps.auths_api.urls' from '/home/roger/proyectos/learning/learning/ioteca_service/ioteca_service_apps/auths_api/urls.py'> (None:None) ^api/auths/>], [<RegexURLResolver <module 'ioteca_service_apps.dper.urls' from '/home/roger/proyectos/learning/learning/ioteca_service/ioteca_service_apps/dper/urls.py'> (None:None) ^api/dper/>]], 'path': 'favicon.ico'}

During handling of the above exception, another exception occurred:

Traceback (most recent call last):
  File "/home/roger/.virtualenvs/learning/lib/python3.5/site-packages/django/template/base.py", line 883, in _resolve_lookup
    current = current[bit]
TypeError: 'RegexURLResolver' object is not subscriptable

During handling of the above exception, another exception occurred:

Traceback (most recent call last):
  File "/home/roger/.virtualenvs/learning/lib/python3.5/site-packages/django/template/base.py", line 891, in _resolve_lookup
    current = getattr(current, bit)
AttributeError: 'RegexURLResolver' object has no attribute 'name'

During handling of the above exception, another exception occurred:

Traceback (most recent call last):
  File "/home/roger/.virtualenvs/learning/lib/python3.5/site-packages/django/template/base.py", line 898, in _resolve_lookup
    current = current[int(bit)]
ValueError: invalid literal for int() with base 10: 'name'

During handling of the above exception, another exception occurred:

Traceback (most recent call last):
  File "/home/roger/.virtualenvs/learning/lib/python3.5/site-packages/django/template/base.py", line 905, in _resolve_lookup
    (bit, current))  # missing attribute
django.template.base.VariableDoesNotExist: Failed lookup for key [name] in "<RegexURLResolver <module 'django.contrib.admindocs.urls' from '/home/roger/.virtualenvs/learning/lib/python3.5/site-packages/django/contrib/admindocs/urls.py'> (None:None) ^admin/doc/>"
[2016-11-19 23:21:56] DEBUG [django.template:927] Exception while resolving variable 'name' in template 'unknown'.
Traceback (most recent call last):
  File "/home/roger/.virtualenvs/learning/lib/python3.5/site-packages/django/core/handlers/base.py", line 134, in get_response
    resolver_match = resolver.resolve(request.path_info)
  File "/home/roger/.virtualenvs/learning/lib/python3.5/site-packages/django/core/urlresolvers.py", line 404, in resolve
    raise Resolver404({'tried': tried, 'path': new_path})
django.core.urlresolvers.Resolver404: {'tried': [[<RegexURLResolver <RegexURLPattern list> (admin:admin) ^admin/>], [<RegexURLResolver <module 'django.contrib.admindocs.urls' from '/home/roger/.virtualenvs/learning/lib/python3.5/site-packages/django/contrib/admindocs/urls.py'> (None:None) ^admin/doc/>], [<RegexURLResolver <module 'rest_framework.urls' from '/home/roger/.virtualenvs/learning/lib/python3.5/site-packages/rest_framework/urls.py'> (rest_framework:rest_framework) ^api-auth/>], [<RegexURLResolver <module 'oauth2_provider.urls' from '/home/roger/.virtualenvs/learning/lib/python3.5/site-packages/oauth2_provider/urls.py'> (None:oauth2_provider) ^o/>], [<RegexURLResolver <module 'ioteca_service_apps.auths_api.urls' from '/home/roger/proyectos/learning/learning/ioteca_service/ioteca_service_apps/auths_api/urls.py'> (None:None) ^api/auths/>], [<RegexURLResolver <module 'ioteca_service_apps.dper.urls' from '/home/roger/proyectos/learning/learning/ioteca_service/ioteca_service_apps/dper/urls.py'> (None:None) ^api/dper/>]], 'path': 'favicon.ico'}

During handling of the above exception, another exception occurred:

Traceback (most recent call last):
  File "/home/roger/.virtualenvs/learning/lib/python3.5/site-packages/django/template/base.py", line 883, in _resolve_lookup
    current = current[bit]
TypeError: 'RegexURLResolver' object is not subscriptable

During handling of the above exception, another exception occurred:

Traceback (most recent call last):
  File "/home/roger/.virtualenvs/learning/lib/python3.5/site-packages/django/template/base.py", line 891, in _resolve_lookup
    current = getattr(current, bit)
AttributeError: 'RegexURLResolver' object has no attribute 'name'

During handling of the above exception, another exception occurred:

Traceback (most recent call last):
  File "/home/roger/.virtualenvs/learning/lib/python3.5/site-packages/django/template/base.py", line 898, in _resolve_lookup
    current = current[int(bit)]
ValueError: invalid literal for int() with base 10: 'name'

During handling of the above exception, another exception occurred:

Traceback (most recent call last):
  File "/home/roger/.virtualenvs/learning/lib/python3.5/site-packages/django/template/base.py", line 905, in _resolve_lookup
    (bit, current))  # missing attribute
django.template.base.VariableDoesNotExist: Failed lookup for key [name] in "<RegexURLResolver <module 'rest_framework.urls' from '/home/roger/.virtualenvs/learning/lib/python3.5/site-packages/rest_framework/urls.py'> (rest_framework:rest_framework) ^api-auth/>"
[2016-11-19 23:21:56] DEBUG [django.template:927] Exception while resolving variable 'name' in template 'unknown'.
Traceback (most recent call last):
  File "/home/roger/.virtualenvs/learning/lib/python3.5/site-packages/django/core/handlers/base.py", line 134, in get_response
    resolver_match = resolver.resolve(request.path_info)
  File "/home/roger/.virtualenvs/learning/lib/python3.5/site-packages/django/core/urlresolvers.py", line 404, in resolve
    raise Resolver404({'tried': tried, 'path': new_path})
django.core.urlresolvers.Resolver404: {'tried': [[<RegexURLResolver <RegexURLPattern list> (admin:admin) ^admin/>], [<RegexURLResolver <module 'django.contrib.admindocs.urls' from '/home/roger/.virtualenvs/learning/lib/python3.5/site-packages/django/contrib/admindocs/urls.py'> (None:None) ^admin/doc/>], [<RegexURLResolver <module 'rest_framework.urls' from '/home/roger/.virtualenvs/learning/lib/python3.5/site-packages/rest_framework/urls.py'> (rest_framework:rest_framework) ^api-auth/>], [<RegexURLResolver <module 'oauth2_provider.urls' from '/home/roger/.virtualenvs/learning/lib/python3.5/site-packages/oauth2_provider/urls.py'> (None:oauth2_provider) ^o/>], [<RegexURLResolver <module 'ioteca_service_apps.auths_api.urls' from '/home/roger/proyectos/learning/learning/ioteca_service/ioteca_service_apps/auths_api/urls.py'> (None:None) ^api/auths/>], [<RegexURLResolver <module 'ioteca_service_apps.dper.urls' from '/home/roger/proyectos/learning/learning/ioteca_service/ioteca_service_apps/dper/urls.py'> (None:None) ^api/dper/>]], 'path': 'favicon.ico'}

During handling of the above exception, another exception occurred:

Traceback (most recent call last):
  File "/home/roger/.virtualenvs/learning/lib/python3.5/site-packages/django/template/base.py", line 883, in _resolve_lookup
    current = current[bit]
TypeError: 'RegexURLResolver' object is not subscriptable

During handling of the above exception, another exception occurred:

Traceback (most recent call last):
  File "/home/roger/.virtualenvs/learning/lib/python3.5/site-packages/django/template/base.py", line 891, in _resolve_lookup
    current = getattr(current, bit)
AttributeError: 'RegexURLResolver' object has no attribute 'name'

During handling of the above exception, another exception occurred:

Traceback (most recent call last):
  File "/home/roger/.virtualenvs/learning/lib/python3.5/site-packages/django/template/base.py", line 898, in _resolve_lookup
    current = current[int(bit)]
ValueError: invalid literal for int() with base 10: 'name'

During handling of the above exception, another exception occurred:

Traceback (most recent call last):
  File "/home/roger/.virtualenvs/learning/lib/python3.5/site-packages/django/template/base.py", line 905, in _resolve_lookup
    (bit, current))  # missing attribute
django.template.base.VariableDoesNotExist: Failed lookup for key [name] in "<RegexURLResolver <module 'oauth2_provider.urls' from '/home/roger/.virtualenvs/learning/lib/python3.5/site-packages/oauth2_provider/urls.py'> (None:oauth2_provider) ^o/>"
[2016-11-19 23:21:56] DEBUG [django.template:927] Exception while resolving variable 'name' in template 'unknown'.
Traceback (most recent call last):
  File "/home/roger/.virtualenvs/learning/lib/python3.5/site-packages/django/core/handlers/base.py", line 134, in get_response
    resolver_match = resolver.resolve(request.path_info)
  File "/home/roger/.virtualenvs/learning/lib/python3.5/site-packages/django/core/urlresolvers.py", line 404, in resolve
    raise Resolver404({'tried': tried, 'path': new_path})
django.core.urlresolvers.Resolver404: {'tried': [[<RegexURLResolver <RegexURLPattern list> (admin:admin) ^admin/>], [<RegexURLResolver <module 'django.contrib.admindocs.urls' from '/home/roger/.virtualenvs/learning/lib/python3.5/site-packages/django/contrib/admindocs/urls.py'> (None:None) ^admin/doc/>], [<RegexURLResolver <module 'rest_framework.urls' from '/home/roger/.virtualenvs/learning/lib/python3.5/site-packages/rest_framework/urls.py'> (rest_framework:rest_framework) ^api-auth/>], [<RegexURLResolver <module 'oauth2_provider.urls' from '/home/roger/.virtualenvs/learning/lib/python3.5/site-packages/oauth2_provider/urls.py'> (None:oauth2_provider) ^o/>], [<RegexURLResolver <module 'ioteca_service_apps.auths_api.urls' from '/home/roger/proyectos/learning/learning/ioteca_service/ioteca_service_apps/auths_api/urls.py'> (None:None) ^api/auths/>], [<RegexURLResolver <module 'ioteca_service_apps.dper.urls' from '/home/roger/proyectos/learning/learning/ioteca_service/ioteca_service_apps/dper/urls.py'> (None:None) ^api/dper/>]], 'path': 'favicon.ico'}

During handling of the above exception, another exception occurred:

Traceback (most recent call last):
  File "/home/roger/.virtualenvs/learning/lib/python3.5/site-packages/django/template/base.py", line 883, in _resolve_lookup
    current = current[bit]
TypeError: 'RegexURLResolver' object is not subscriptable

During handling of the above exception, another exception occurred:

Traceback (most recent call last):
  File "/home/roger/.virtualenvs/learning/lib/python3.5/site-packages/django/template/base.py", line 891, in _resolve_lookup
    current = getattr(current, bit)
AttributeError: 'RegexURLResolver' object has no attribute 'name'

During handling of the above exception, another exception occurred:

Traceback (most recent call last):
  File "/home/roger/.virtualenvs/learning/lib/python3.5/site-packages/django/template/base.py", line 898, in _resolve_lookup
    current = current[int(bit)]
ValueError: invalid literal for int() with base 10: 'name'

During handling of the above exception, another exception occurred:

Traceback (most recent call last):
  File "/home/roger/.virtualenvs/learning/lib/python3.5/site-packages/django/template/base.py", line 905, in _resolve_lookup
    (bit, current))  # missing attribute
django.template.base.VariableDoesNotExist: Failed lookup for key [name] in "<RegexURLResolver <module 'ioteca_service_apps.auths_api.urls' from '/home/roger/proyectos/learning/learning/ioteca_service/ioteca_service_apps/auths_api/urls.py'> (None:None) ^api/auths/>"
[2016-11-19 23:21:56] DEBUG [django.template:927] Exception while resolving variable 'name' in template 'unknown'.
Traceback (most recent call last):
  File "/home/roger/.virtualenvs/learning/lib/python3.5/site-packages/django/core/handlers/base.py", line 134, in get_response
    resolver_match = resolver.resolve(request.path_info)
  File "/home/roger/.virtualenvs/learning/lib/python3.5/site-packages/django/core/urlresolvers.py", line 404, in resolve
    raise Resolver404({'tried': tried, 'path': new_path})
django.core.urlresolvers.Resolver404: {'tried': [[<RegexURLResolver <RegexURLPattern list> (admin:admin) ^admin/>], [<RegexURLResolver <module 'django.contrib.admindocs.urls' from '/home/roger/.virtualenvs/learning/lib/python3.5/site-packages/django/contrib/admindocs/urls.py'> (None:None) ^admin/doc/>], [<RegexURLResolver <module 'rest_framework.urls' from '/home/roger/.virtualenvs/learning/lib/python3.5/site-packages/rest_framework/urls.py'> (rest_framework:rest_framework) ^api-auth/>], [<RegexURLResolver <module 'oauth2_provider.urls' from '/home/roger/.virtualenvs/learning/lib/python3.5/site-packages/oauth2_provider/urls.py'> (None:oauth2_provider) ^o/>], [<RegexURLResolver <module 'ioteca_service_apps.auths_api.urls' from '/home/roger/proyectos/learning/learning/ioteca_service/ioteca_service_apps/auths_api/urls.py'> (None:None) ^api/auths/>], [<RegexURLResolver <module 'ioteca_service_apps.dper.urls' from '/home/roger/proyectos/learning/learning/ioteca_service/ioteca_service_apps/dper/urls.py'> (None:None) ^api/dper/>]], 'path': 'favicon.ico'}

During handling of the above exception, another exception occurred:

Traceback (most recent call last):
  File "/home/roger/.virtualenvs/learning/lib/python3.5/site-packages/django/template/base.py", line 883, in _resolve_lookup
    current = current[bit]
TypeError: 'RegexURLResolver' object is not subscriptable

During handling of the above exception, another exception occurred:

Traceback (most recent call last):
  File "/home/roger/.virtualenvs/learning/lib/python3.5/site-packages/django/template/base.py", line 891, in _resolve_lookup
    current = getattr(current, bit)
AttributeError: 'RegexURLResolver' object has no attribute 'name'

During handling of the above exception, another exception occurred:

Traceback (most recent call last):
  File "/home/roger/.virtualenvs/learning/lib/python3.5/site-packages/django/template/base.py", line 898, in _resolve_lookup
    current = current[int(bit)]
ValueError: invalid literal for int() with base 10: 'name'

During handling of the above exception, another exception occurred:

Traceback (most recent call last):
  File "/home/roger/.virtualenvs/learning/lib/python3.5/site-packages/django/template/base.py", line 905, in _resolve_lookup
    (bit, current))  # missing attribute
django.template.base.VariableDoesNotExist: Failed lookup for key [name] in "<RegexURLResolver <module 'ioteca_service_apps.dper.urls' from '/home/roger/proyectos/learning/learning/ioteca_service/ioteca_service_apps/dper/urls.py'> (None:None) ^api/dper/>"
[2016-11-19 23:22:00] WARNING [django.request:182] Not Found: /
[2016-11-19 23:22:00] DEBUG [django.template:927] Exception while resolving variable 'name' in template 'unknown'.
Traceback (most recent call last):
  File "/home/roger/.virtualenvs/learning/lib/python3.5/site-packages/django/core/handlers/base.py", line 134, in get_response
    resolver_match = resolver.resolve(request.path_info)
  File "/home/roger/.virtualenvs/learning/lib/python3.5/site-packages/django/core/urlresolvers.py", line 404, in resolve
    raise Resolver404({'tried': tried, 'path': new_path})
django.core.urlresolvers.Resolver404: {'tried': [[<RegexURLResolver <RegexURLPattern list> (admin:admin) ^admin/>], [<RegexURLResolver <module 'django.contrib.admindocs.urls' from '/home/roger/.virtualenvs/learning/lib/python3.5/site-packages/django/contrib/admindocs/urls.py'> (None:None) ^admin/doc/>], [<RegexURLResolver <module 'rest_framework.urls' from '/home/roger/.virtualenvs/learning/lib/python3.5/site-packages/rest_framework/urls.py'> (rest_framework:rest_framework) ^api-auth/>], [<RegexURLResolver <module 'oauth2_provider.urls' from '/home/roger/.virtualenvs/learning/lib/python3.5/site-packages/oauth2_provider/urls.py'> (None:oauth2_provider) ^o/>], [<RegexURLResolver <module 'ioteca_service_apps.auths_api.urls' from '/home/roger/proyectos/learning/learning/ioteca_service/ioteca_service_apps/auths_api/urls.py'> (None:None) ^api/auths/>], [<RegexURLResolver <module 'ioteca_service_apps.dper.urls' from '/home/roger/proyectos/learning/learning/ioteca_service/ioteca_service_apps/dper/urls.py'> (None:None) ^api/dper/>]], 'path': ''}

During handling of the above exception, another exception occurred:

Traceback (most recent call last):
  File "/home/roger/.virtualenvs/learning/lib/python3.5/site-packages/django/template/base.py", line 883, in _resolve_lookup
    current = current[bit]
TypeError: 'RegexURLResolver' object is not subscriptable

During handling of the above exception, another exception occurred:

Traceback (most recent call last):
  File "/home/roger/.virtualenvs/learning/lib/python3.5/site-packages/django/template/base.py", line 891, in _resolve_lookup
    current = getattr(current, bit)
AttributeError: 'RegexURLResolver' object has no attribute 'name'

During handling of the above exception, another exception occurred:

Traceback (most recent call last):
  File "/home/roger/.virtualenvs/learning/lib/python3.5/site-packages/django/template/base.py", line 898, in _resolve_lookup
    current = current[int(bit)]
ValueError: invalid literal for int() with base 10: 'name'

During handling of the above exception, another exception occurred:

Traceback (most recent call last):
  File "/home/roger/.virtualenvs/learning/lib/python3.5/site-packages/django/template/base.py", line 905, in _resolve_lookup
    (bit, current))  # missing attribute
django.template.base.VariableDoesNotExist: Failed lookup for key [name] in '<RegexURLResolver <RegexURLPattern list> (admin:admin) ^admin/>'
[2016-11-19 23:22:00] DEBUG [django.template:927] Exception while resolving variable 'name' in template 'unknown'.
Traceback (most recent call last):
  File "/home/roger/.virtualenvs/learning/lib/python3.5/site-packages/django/core/handlers/base.py", line 134, in get_response
    resolver_match = resolver.resolve(request.path_info)
  File "/home/roger/.virtualenvs/learning/lib/python3.5/site-packages/django/core/urlresolvers.py", line 404, in resolve
    raise Resolver404({'tried': tried, 'path': new_path})
django.core.urlresolvers.Resolver404: {'tried': [[<RegexURLResolver <RegexURLPattern list> (admin:admin) ^admin/>], [<RegexURLResolver <module 'django.contrib.admindocs.urls' from '/home/roger/.virtualenvs/learning/lib/python3.5/site-packages/django/contrib/admindocs/urls.py'> (None:None) ^admin/doc/>], [<RegexURLResolver <module 'rest_framework.urls' from '/home/roger/.virtualenvs/learning/lib/python3.5/site-packages/rest_framework/urls.py'> (rest_framework:rest_framework) ^api-auth/>], [<RegexURLResolver <module 'oauth2_provider.urls' from '/home/roger/.virtualenvs/learning/lib/python3.5/site-packages/oauth2_provider/urls.py'> (None:oauth2_provider) ^o/>], [<RegexURLResolver <module 'ioteca_service_apps.auths_api.urls' from '/home/roger/proyectos/learning/learning/ioteca_service/ioteca_service_apps/auths_api/urls.py'> (None:None) ^api/auths/>], [<RegexURLResolver <module 'ioteca_service_apps.dper.urls' from '/home/roger/proyectos/learning/learning/ioteca_service/ioteca_service_apps/dper/urls.py'> (None:None) ^api/dper/>]], 'path': ''}

During handling of the above exception, another exception occurred:

Traceback (most recent call last):
  File "/home/roger/.virtualenvs/learning/lib/python3.5/site-packages/django/template/base.py", line 883, in _resolve_lookup
    current = current[bit]
TypeError: 'RegexURLResolver' object is not subscriptable

During handling of the above exception, another exception occurred:

Traceback (most recent call last):
  File "/home/roger/.virtualenvs/learning/lib/python3.5/site-packages/django/template/base.py", line 891, in _resolve_lookup
    current = getattr(current, bit)
AttributeError: 'RegexURLResolver' object has no attribute 'name'

During handling of the above exception, another exception occurred:

Traceback (most recent call last):
  File "/home/roger/.virtualenvs/learning/lib/python3.5/site-packages/django/template/base.py", line 898, in _resolve_lookup
    current = current[int(bit)]
ValueError: invalid literal for int() with base 10: 'name'

During handling of the above exception, another exception occurred:

Traceback (most recent call last):
  File "/home/roger/.virtualenvs/learning/lib/python3.5/site-packages/django/template/base.py", line 905, in _resolve_lookup
    (bit, current))  # missing attribute
django.template.base.VariableDoesNotExist: Failed lookup for key [name] in "<RegexURLResolver <module 'django.contrib.admindocs.urls' from '/home/roger/.virtualenvs/learning/lib/python3.5/site-packages/django/contrib/admindocs/urls.py'> (None:None) ^admin/doc/>"
[2016-11-19 23:22:00] DEBUG [django.template:927] Exception while resolving variable 'name' in template 'unknown'.
Traceback (most recent call last):
  File "/home/roger/.virtualenvs/learning/lib/python3.5/site-packages/django/core/handlers/base.py", line 134, in get_response
    resolver_match = resolver.resolve(request.path_info)
  File "/home/roger/.virtualenvs/learning/lib/python3.5/site-packages/django/core/urlresolvers.py", line 404, in resolve
    raise Resolver404({'tried': tried, 'path': new_path})
django.core.urlresolvers.Resolver404: {'tried': [[<RegexURLResolver <RegexURLPattern list> (admin:admin) ^admin/>], [<RegexURLResolver <module 'django.contrib.admindocs.urls' from '/home/roger/.virtualenvs/learning/lib/python3.5/site-packages/django/contrib/admindocs/urls.py'> (None:None) ^admin/doc/>], [<RegexURLResolver <module 'rest_framework.urls' from '/home/roger/.virtualenvs/learning/lib/python3.5/site-packages/rest_framework/urls.py'> (rest_framework:rest_framework) ^api-auth/>], [<RegexURLResolver <module 'oauth2_provider.urls' from '/home/roger/.virtualenvs/learning/lib/python3.5/site-packages/oauth2_provider/urls.py'> (None:oauth2_provider) ^o/>], [<RegexURLResolver <module 'ioteca_service_apps.auths_api.urls' from '/home/roger/proyectos/learning/learning/ioteca_service/ioteca_service_apps/auths_api/urls.py'> (None:None) ^api/auths/>], [<RegexURLResolver <module 'ioteca_service_apps.dper.urls' from '/home/roger/proyectos/learning/learning/ioteca_service/ioteca_service_apps/dper/urls.py'> (None:None) ^api/dper/>]], 'path': ''}

During handling of the above exception, another exception occurred:

Traceback (most recent call last):
  File "/home/roger/.virtualenvs/learning/lib/python3.5/site-packages/django/template/base.py", line 883, in _resolve_lookup
    current = current[bit]
TypeError: 'RegexURLResolver' object is not subscriptable

During handling of the above exception, another exception occurred:

Traceback (most recent call last):
  File "/home/roger/.virtualenvs/learning/lib/python3.5/site-packages/django/template/base.py", line 891, in _resolve_lookup
    current = getattr(current, bit)
AttributeError: 'RegexURLResolver' object has no attribute 'name'

During handling of the above exception, another exception occurred:

Traceback (most recent call last):
  File "/home/roger/.virtualenvs/learning/lib/python3.5/site-packages/django/template/base.py", line 898, in _resolve_lookup
    current = current[int(bit)]
ValueError: invalid literal for int() with base 10: 'name'

During handling of the above exception, another exception occurred:

Traceback (most recent call last):
  File "/home/roger/.virtualenvs/learning/lib/python3.5/site-packages/django/template/base.py", line 905, in _resolve_lookup
    (bit, current))  # missing attribute
django.template.base.VariableDoesNotExist: Failed lookup for key [name] in "<RegexURLResolver <module 'rest_framework.urls' from '/home/roger/.virtualenvs/learning/lib/python3.5/site-packages/rest_framework/urls.py'> (rest_framework:rest_framework) ^api-auth/>"
[2016-11-19 23:22:00] DEBUG [django.template:927] Exception while resolving variable 'name' in template 'unknown'.
Traceback (most recent call last):
  File "/home/roger/.virtualenvs/learning/lib/python3.5/site-packages/django/core/handlers/base.py", line 134, in get_response
    resolver_match = resolver.resolve(request.path_info)
  File "/home/roger/.virtualenvs/learning/lib/python3.5/site-packages/django/core/urlresolvers.py", line 404, in resolve
    raise Resolver404({'tried': tried, 'path': new_path})
django.core.urlresolvers.Resolver404: {'tried': [[<RegexURLResolver <RegexURLPattern list> (admin:admin) ^admin/>], [<RegexURLResolver <module 'django.contrib.admindocs.urls' from '/home/roger/.virtualenvs/learning/lib/python3.5/site-packages/django/contrib/admindocs/urls.py'> (None:None) ^admin/doc/>], [<RegexURLResolver <module 'rest_framework.urls' from '/home/roger/.virtualenvs/learning/lib/python3.5/site-packages/rest_framework/urls.py'> (rest_framework:rest_framework) ^api-auth/>], [<RegexURLResolver <module 'oauth2_provider.urls' from '/home/roger/.virtualenvs/learning/lib/python3.5/site-packages/oauth2_provider/urls.py'> (None:oauth2_provider) ^o/>], [<RegexURLResolver <module 'ioteca_service_apps.auths_api.urls' from '/home/roger/proyectos/learning/learning/ioteca_service/ioteca_service_apps/auths_api/urls.py'> (None:None) ^api/auths/>], [<RegexURLResolver <module 'ioteca_service_apps.dper.urls' from '/home/roger/proyectos/learning/learning/ioteca_service/ioteca_service_apps/dper/urls.py'> (None:None) ^api/dper/>]], 'path': ''}

During handling of the above exception, another exception occurred:

Traceback (most recent call last):
  File "/home/roger/.virtualenvs/learning/lib/python3.5/site-packages/django/template/base.py", line 883, in _resolve_lookup
    current = current[bit]
TypeError: 'RegexURLResolver' object is not subscriptable

During handling of the above exception, another exception occurred:

Traceback (most recent call last):
  File "/home/roger/.virtualenvs/learning/lib/python3.5/site-packages/django/template/base.py", line 891, in _resolve_lookup
    current = getattr(current, bit)
AttributeError: 'RegexURLResolver' object has no attribute 'name'

During handling of the above exception, another exception occurred:

Traceback (most recent call last):
  File "/home/roger/.virtualenvs/learning/lib/python3.5/site-packages/django/template/base.py", line 898, in _resolve_lookup
    current = current[int(bit)]
ValueError: invalid literal for int() with base 10: 'name'

During handling of the above exception, another exception occurred:

Traceback (most recent call last):
  File "/home/roger/.virtualenvs/learning/lib/python3.5/site-packages/django/template/base.py", line 905, in _resolve_lookup
    (bit, current))  # missing attribute
django.template.base.VariableDoesNotExist: Failed lookup for key [name] in "<RegexURLResolver <module 'oauth2_provider.urls' from '/home/roger/.virtualenvs/learning/lib/python3.5/site-packages/oauth2_provider/urls.py'> (None:oauth2_provider) ^o/>"
[2016-11-19 23:22:00] DEBUG [django.template:927] Exception while resolving variable 'name' in template 'unknown'.
Traceback (most recent call last):
  File "/home/roger/.virtualenvs/learning/lib/python3.5/site-packages/django/core/handlers/base.py", line 134, in get_response
    resolver_match = resolver.resolve(request.path_info)
  File "/home/roger/.virtualenvs/learning/lib/python3.5/site-packages/django/core/urlresolvers.py", line 404, in resolve
    raise Resolver404({'tried': tried, 'path': new_path})
django.core.urlresolvers.Resolver404: {'tried': [[<RegexURLResolver <RegexURLPattern list> (admin:admin) ^admin/>], [<RegexURLResolver <module 'django.contrib.admindocs.urls' from '/home/roger/.virtualenvs/learning/lib/python3.5/site-packages/django/contrib/admindocs/urls.py'> (None:None) ^admin/doc/>], [<RegexURLResolver <module 'rest_framework.urls' from '/home/roger/.virtualenvs/learning/lib/python3.5/site-packages/rest_framework/urls.py'> (rest_framework:rest_framework) ^api-auth/>], [<RegexURLResolver <module 'oauth2_provider.urls' from '/home/roger/.virtualenvs/learning/lib/python3.5/site-packages/oauth2_provider/urls.py'> (None:oauth2_provider) ^o/>], [<RegexURLResolver <module 'ioteca_service_apps.auths_api.urls' from '/home/roger/proyectos/learning/learning/ioteca_service/ioteca_service_apps/auths_api/urls.py'> (None:None) ^api/auths/>], [<RegexURLResolver <module 'ioteca_service_apps.dper.urls' from '/home/roger/proyectos/learning/learning/ioteca_service/ioteca_service_apps/dper/urls.py'> (None:None) ^api/dper/>]], 'path': ''}

During handling of the above exception, another exception occurred:

Traceback (most recent call last):
  File "/home/roger/.virtualenvs/learning/lib/python3.5/site-packages/django/template/base.py", line 883, in _resolve_lookup
    current = current[bit]
TypeError: 'RegexURLResolver' object is not subscriptable

During handling of the above exception, another exception occurred:

Traceback (most recent call last):
  File "/home/roger/.virtualenvs/learning/lib/python3.5/site-packages/django/template/base.py", line 891, in _resolve_lookup
    current = getattr(current, bit)
AttributeError: 'RegexURLResolver' object has no attribute 'name'

During handling of the above exception, another exception occurred:

Traceback (most recent call last):
  File "/home/roger/.virtualenvs/learning/lib/python3.5/site-packages/django/template/base.py", line 898, in _resolve_lookup
    current = current[int(bit)]
ValueError: invalid literal for int() with base 10: 'name'

During handling of the above exception, another exception occurred:

Traceback (most recent call last):
  File "/home/roger/.virtualenvs/learning/lib/python3.5/site-packages/django/template/base.py", line 905, in _resolve_lookup
    (bit, current))  # missing attribute
django.template.base.VariableDoesNotExist: Failed lookup for key [name] in "<RegexURLResolver <module 'ioteca_service_apps.auths_api.urls' from '/home/roger/proyectos/learning/learning/ioteca_service/ioteca_service_apps/auths_api/urls.py'> (None:None) ^api/auths/>"
[2016-11-19 23:22:00] DEBUG [django.template:927] Exception while resolving variable 'name' in template 'unknown'.
Traceback (most recent call last):
  File "/home/roger/.virtualenvs/learning/lib/python3.5/site-packages/django/core/handlers/base.py", line 134, in get_response
    resolver_match = resolver.resolve(request.path_info)
  File "/home/roger/.virtualenvs/learning/lib/python3.5/site-packages/django/core/urlresolvers.py", line 404, in resolve
    raise Resolver404({'tried': tried, 'path': new_path})
django.core.urlresolvers.Resolver404: {'tried': [[<RegexURLResolver <RegexURLPattern list> (admin:admin) ^admin/>], [<RegexURLResolver <module 'django.contrib.admindocs.urls' from '/home/roger/.virtualenvs/learning/lib/python3.5/site-packages/django/contrib/admindocs/urls.py'> (None:None) ^admin/doc/>], [<RegexURLResolver <module 'rest_framework.urls' from '/home/roger/.virtualenvs/learning/lib/python3.5/site-packages/rest_framework/urls.py'> (rest_framework:rest_framework) ^api-auth/>], [<RegexURLResolver <module 'oauth2_provider.urls' from '/home/roger/.virtualenvs/learning/lib/python3.5/site-packages/oauth2_provider/urls.py'> (None:oauth2_provider) ^o/>], [<RegexURLResolver <module 'ioteca_service_apps.auths_api.urls' from '/home/roger/proyectos/learning/learning/ioteca_service/ioteca_service_apps/auths_api/urls.py'> (None:None) ^api/auths/>], [<RegexURLResolver <module 'ioteca_service_apps.dper.urls' from '/home/roger/proyectos/learning/learning/ioteca_service/ioteca_service_apps/dper/urls.py'> (None:None) ^api/dper/>]], 'path': ''}

During handling of the above exception, another exception occurred:

Traceback (most recent call last):
  File "/home/roger/.virtualenvs/learning/lib/python3.5/site-packages/django/template/base.py", line 883, in _resolve_lookup
    current = current[bit]
TypeError: 'RegexURLResolver' object is not subscriptable

During handling of the above exception, another exception occurred:

Traceback (most recent call last):
  File "/home/roger/.virtualenvs/learning/lib/python3.5/site-packages/django/template/base.py", line 891, in _resolve_lookup
    current = getattr(current, bit)
AttributeError: 'RegexURLResolver' object has no attribute 'name'

During handling of the above exception, another exception occurred:

Traceback (most recent call last):
  File "/home/roger/.virtualenvs/learning/lib/python3.5/site-packages/django/template/base.py", line 898, in _resolve_lookup
    current = current[int(bit)]
ValueError: invalid literal for int() with base 10: 'name'

During handling of the above exception, another exception occurred:

Traceback (most recent call last):
  File "/home/roger/.virtualenvs/learning/lib/python3.5/site-packages/django/template/base.py", line 905, in _resolve_lookup
    (bit, current))  # missing attribute
django.template.base.VariableDoesNotExist: Failed lookup for key [name] in "<RegexURLResolver <module 'ioteca_service_apps.dper.urls' from '/home/roger/proyectos/learning/learning/ioteca_service/ioteca_service_apps/dper/urls.py'> (None:None) ^api/dper/>"
